<?xml version="1.0" encoding="utf-8"?>
<robot xmlns:xacro="http://www.ros.org/wiki/xacro" name="arm">
  <xacro:macro name="arm" params="prefix parent_link xyz='0 0 0' rpy='0 0 0'">
    <link
      name="${prefix}base_link_alex">
      <inertial>
        <origin
          xyz="-0.05930869488714 -2.87595388123997E-12 0.0776653157730273"
          rpy="0 0 0" />
        <mass
          value="33.891578448587" />
        <inertia
          ixx="0.562042604088221"
          ixy="-9.14377057009813E-12"
          ixz="0.00403961419511078"
          iyy="0.970694427805805"
          iyz="-7.30601565928646E-12"
          izz="1.29713482615658" />
      </inertial>
      <visual>
        <origin
          xyz="0 0 0"
          rpy="0 0 0" />
        <geometry>
          <mesh
            filename="package://my_robot_urdf/meshes/base_link_alex.STL" />
        </geometry>
        <material
          name="">
          <color
            rgba="0.152941176470588 0 0.117647058823529 1" />
        </material>
      </visual>
      <collision>
        <origin
          xyz="0 0 0"
          rpy="0 0 0" />
        <geometry>
          <mesh
            filename="package://my_robot_urdf/meshes/base_link_alex.STL" />
        </geometry>
      </collision>
    </link>
    <!-- Define the joint connecting this arm to the parent link -->
    <joint name="${prefix}base_joint_alex" type="fixed">
      <origin xyz="${xyz}" rpy="${rpy}" />
      <parent link="${parent_link}" />
      <child link="${prefix}base_link_alex" />
    </joint>
    <link
      name="${prefix}arm_link_1_alex">
      <inertial>
        <origin
          xyz="0.0416589398280025 -3.68988089329334E-05 0.19712083516126"
          rpy="0 0 0" />
        <mass
          value="26.7048266497369" />
        <inertia
          ixx="0.495499615132855"
          ixy="-0.0102760504758245"
          ixz="-0.0600935399650257"
          iyy="0.766768677077223"
          iyz="-0.0115358881770517"
          izz="0.604967931690783" />
      </inertial>
      <visual>
        <origin
          xyz="0 0 0"
          rpy="0 0 0" />
        <geometry>
          <mesh
            filename="package://my_robot_urdf/meshes/arm_link_1_alex.STL" />
        </geometry>
        <material
          name="">
          <color
            rgba="1 0 0 1" />
        </material>
      </visual>
      <collision>
        <origin
          xyz="0 0 0"
          rpy="0 0 0" />
        <geometry>
          <mesh
            filename="package://my_robot_urdf/meshes/arm_link_1_alex.STL" />
        </geometry>
      </collision>
    </link>
    <joint
      name="${prefix}arm_joint_1_alex"
      type="revolute">
      <origin
        xyz="0 0 0.234"
        rpy="0 0 0" />
      <parent
        link="${prefix}base_link_alex" />
      <child
        link="${prefix}arm_link_1_alex" />
      <axis
        xyz="0 0 1" />
      <limit
        lower="-3.1416"
        upper="3.1416"
        effort="0"
        velocity="0" />
    </joint>
    <link
      name="${prefix}arm_link_2_alex">
      <inertial>
        <origin
          xyz="0.000258724363916746 -0.0707589768311214 0.290203503422467"
          rpy="0 0 0" />
        <mass
          value="14.3270690802686" />
        <inertia
          ixx="0.848873613210201"
          ixy="0.000175299197197544"
          ixz="-4.64678003354308E-05"
          iyy="0.874803778149419"
          iyz="0.0137202067906074"
          izz="0.0504590836189902" />
      </inertial>
      <visual>
        <origin
          xyz="0 0 0"
          rpy="0 0 0" />
        <geometry>
          <mesh
            filename="package://my_robot_urdf/meshes/arm_link_2_alex.STL" />
        </geometry>
        <material
          name="">
          <color
            rgba="0.792156862745098 0.819607843137255 0.933333333333333 1" />
        </material>
      </visual>
      <collision>
        <origin
          xyz="0 0 0"
          rpy="0 0 0" />
        <geometry>
          <mesh
            filename="package://my_robot_urdf/meshes/arm_link_2_alex.STL" />
        </geometry>
      </collision>
    </link>
    <joint
      name="${prefix}arm_joint_2_alex"
      type="revolute">
      <origin
        xyz="0.15 -0.1375 0.265"
        rpy="0 0 0" />
      <parent
        link="${prefix}arm_link_1_alex" />
      <child
        link="${prefix}arm_link_2_alex" />
      <axis
        xyz="0 1 0" />
      <limit
        lower="-3.1416"
        upper="3.1416"
        effort="0"
        velocity="0" />
    </joint>
    <link
      name="${prefix}arm_link_3_alex">
      <inertial>
        <origin
          xyz="0.0362614171159604 0.143132908024542 0.0664637155357433"
          rpy="0 0 0" />
        <mass
          value="27.1450417424437" />
        <inertia
          ixx="0.344868303293537"
          ixy="0.00338242702861572"
          ixz="-0.0211648441841246"
          iyy="0.473964503565446"
          iyz="-0.00675660536457731"
          izz="0.420912669748457" />
      </inertial>
      <visual>
        <origin
          xyz="0 0 0"
          rpy="0 0 0" />
        <geometry>
          <mesh
            filename="package://my_robot_urdf/meshes/arm_link_3_alex.STL" />
        </geometry>
        <material
          name="">
          <color
            rgba="0.792156862745098 0.819607843137255 0.933333333333333 1" />
        </material>
      </visual>
      <collision>
        <origin
          xyz="0 0 0"
          rpy="0 0 0" />
        <geometry>
          <mesh
            filename="package://my_robot_urdf/meshes/arm_link_3_alex.STL" />
        </geometry>
      </collision>
    </link>
    <joint
      name="${prefix}arm_joint_3_alex"
      type="revolute">
      <origin
        xyz="0 0 0.7"
        rpy="0 0 0" />
      <parent
        link="${prefix}arm_link_2_alex" />
      <child
        link="${prefix}arm_link_3_alex" />
      <axis
        xyz="0 1 0" />
      <limit
        lower="-3.1416"
        upper="3.1416"
        effort="0"
        velocity="0" />
    </joint>
    <link
      name="${prefix}arm_link_4_alex">
      <inertial>
        <origin
          xyz="0.316053837217416 -9.61729624260159E-07 4.81067610857977E-07"
          rpy="0 0 0" />
        <mass
          value="9.30858027519608" />
        <inertia
          ixx="0.0348463133234508"
          ixy="7.6582656016075E-07"
          ixz="3.49084068434524E-07"
          iyy="0.25723918092213"
          iyz="0.000166705964846771"
          izz="0.264212206266023" />
      </inertial>
      <visual>
        <origin
          xyz="0 0 0"
          rpy="0 0 0" />
        <geometry>
          <mesh
            filename="package://my_robot_urdf/meshes/arm_link_4_alex.STL" />
        </geometry>
        <material
          name="">
          <color
            rgba="0.792156862745098 0.819607843137255 0.933333333333333 1" />
        </material>
      </visual>
      <collision>
        <origin
          xyz="0 0 0"
          rpy="0 0 0" />
        <geometry>
          <mesh
            filename="package://my_robot_urdf/meshes/arm_link_4_alex.STL" />
        </geometry>
      </collision>
    </link>
    <joint
      name="${prefix}arm_joint_4_alex"
      type="revolute">
      <origin
        xyz="0.29 0.13 0.115"
        rpy="0 0 0" />
      <parent
        link="${prefix}arm_link_3_alex" />
      <child
        link="${prefix}arm_link_4_alex" />
      <axis
        xyz="1 0 0" />
      <limit
        lower="-3.1416"
        upper="3.1416"
        effort="0"
        velocity="0" />
    </joint>
    <link
      name="${prefix}arm_link_5_alex">
      <inertial>
        <origin
          xyz="-0.00224018993807718 -4.63651143520205E-10 7.93515697594671E-10"
          rpy="0 0 0" />
        <mass
          value="0.961734748124672" />
        <inertia
          ixx="0.00154678090917305"
          ixy="1.419698244829E-11"
          ixz="-8.85889011205107E-10"
          iyy="0.00165625576362529"
          iyz="-9.91727417077089E-10"
          izz="0.00143991315628678" />
      </inertial>
      <visual>
        <origin
          xyz="0 0 0"
          rpy="0 0 0" />
        <geometry>
          <mesh
            filename="package://my_robot_urdf/meshes/arm_link_5_alex.STL" />
        </geometry>
        <material
          name="">
          <color
            rgba="0.792156862745098 0.819607843137255 0.933333333333333 1" />
        </material>
      </visual>
      <collision>
        <origin
          xyz="0 0 0"
          rpy="0 0 0" />
        <geometry>
          <mesh
            filename="package://my_robot_urdf/meshes/arm_link_5_alex.STL" />
        </geometry>
      </collision>
    </link>
    <joint
      name="${prefix}arm_joint_5_alex"
      type="revolute">
      <origin
        xyz="0.51 0 0"
        rpy="0 0 0" />
      <parent
        link="${prefix}arm_link_4_alex" />
      <child
        link="${prefix}arm_link_5_alex" />
      <axis
        xyz="0 1 0" />
      <limit
        lower="-3.1416"
        upper="3.1416"
        effort="0"
        velocity="0" />
    </joint>
    <link
      name="${prefix}arm_link_6_alex">
      <inertial>
        <origin
          xyz="2.47238264115129E-08 2.05183470214365E-09 0.0527259633442777"
          rpy="0 0 0" />
        <mass
          value="0.288779624800079" />
        <inertia
          ixx="0.000386925186804296"
          ixy="-2.51402341991393E-12"
          ixz="-3.11942264818914E-13"
          iyy="0.000386925215104184"
          iyz="-2.74312811357832E-14"
          izz="0.000212753902483571" />
      </inertial>
      <visual>
        <origin
          xyz="0 0 0"
          rpy="0 0 0" />
        <geometry>
          <mesh
            filename="package://my_robot_urdf/meshes/arm_link_6_alex.STL" />
        </geometry>
        <material
          name="">
          <color
            rgba="0.792156862745098 0.819607843137255 0.933333333333333 1" />
        </material>
      </visual>
      <collision>
        <origin
          xyz="0 0 0"
          rpy="0 0 0" />
        <geometry>
          <mesh
            filename="package://my_robot_urdf/meshes/arm_link_6_alex.STL" />
        </geometry>
      </collision>
    </link>
    <joint
      name="${prefix}arm_joint_6_alex"
      type="revolute">
      <origin
        xyz="0.045 0 0"
        rpy="1.5708 0 1.5708" />
      <parent
        link="${prefix}arm_link_5_alex" />
      <child
        link="${prefix}arm_link_6_alex" />
      <axis
        xyz="0 0 1" />
      <limit
        lower="-1.5708"
        upper="4.7124"
        effort="0"
        velocity="0" />
    </joint>
    <link
      name="${prefix}eef_link_alex">
      <inertial>
        <origin
          xyz="2.38264269425414E-13 -2.66453525910038E-15 -0.0980561329200587"
          rpy="0 0 0" />
        <mass
          value="1.45406661810263" />
        <inertia
          ixx="0.00681334885577991"
          ixy="4.74320102087839E-09"
          ixz="-7.63267180505381E-14"
          iyy="0.00863071846569575"
          iyz="4.48393921534639E-16"
          izz="0.00243700011056295" />
      </inertial>
      <visual>
        <origin
          xyz="0 0 0"
          rpy="0 0 0" />
        <geometry>
          <mesh
            filename="package://my_robot_urdf/meshes/eef_link_alex.STL" />
        </geometry>
        <material
          name="">
          <color
            rgba="0.792156862745098 0.819607843137255 0.933333333333333 1" />
        </material>
      </visual>
      <collision>
        <origin
          xyz="0 0 0"
          rpy="0 0 0" />
        <geometry>
          <mesh
            filename="package://my_robot_urdf/meshes/eef_link_alex.STL" />
        </geometry>
      </collision>
    </link>
    <joint
      name="${prefix}eef_joint_fixed_alex"
      type="fixed">
      <origin
        xyz="0 0 0.32173"
        rpy="0 0 3.1416" />
      <parent
        link="${prefix}arm_link_6_alex" />
      <child
        link="${prefix}eef_link_alex" />
      <axis
        xyz="0 0 0" />
    </joint>
  </xacro:macro>
</robot>