<?xml version="1.0" encoding="utf-8"?>
<robot xmlns:xacro="http://www.ros.org/wiki/xacro" name="arm">
    <xacro:macro name="arm_coco" params="prefix parent_link xyz='0 0 0' rpy='0 0 0'">
        <link
            name="${prefix}base_link_coco">
            <inertial>
                <origin
                    xyz="-0.0764021530191945 2.71349348865523E-05 0.0792317455056668"
                    rpy="0 0 0" />
                <mass
                    value="33.7641312353281" />
                <inertia
                    ixx="0.388653917501998"
                    ixy="3.7351572975921E-18"
                    ixz="6.82570301647603E-05"
                    iyy="0.347678993710906"
                    iyz="9.00213723376388E-18"
                    izz="0.646698533818771" />
            </inertial>
            <visual>
                <origin
                    xyz="0 0 0"
                    rpy="0 0 0" />
                <geometry>
                    <mesh
                        filename="package://my_robot_urdf/meshes/base_link_coco.STL" />
                </geometry>
                <material
                    name="">
                    <color
                        rgba="0.792156862745098 0.819607843137255 0.933333333333333 1" />
                </material>
            </visual>
            <collision>
                <origin
                    xyz="0 0 0"
                    rpy="0 0 0" />
                <geometry>
                    <mesh
                        filename="package://my_robot_urdf/meshes/base_link_coco.STL" />
                </geometry>
            </collision>
        </link>
        <!-- Define the joint connecting this arm to the parent link -->
        <joint name="${prefix}base_joint_coco" type="fixed">
            <origin xyz="${xyz}" rpy="${rpy}" />
            <parent link="${parent_link}" />
            <child link="${prefix}base_link_coco" />
        </joint>
        <link
            name="${prefix}arm_link_1_coco">
            <inertial>
                <origin
                    xyz="0.0310954578647585 0.134341853376388 0.00332496023117676"
                    rpy="0 0 0" />
                <mass
                    value="28.7973325809481" />
                <inertia
                    ixx="0.316024916828851"
                    ixy="-0.0129236801369765"
                    ixz="0.000189061034524889"
                    iyy="0.500692862333896"
                    iyz="0.00031691495962207"
                    izz="0.322997369549128" />
            </inertial>
            <visual>
                <origin
                    xyz="0 0 0"
                    rpy="0 0 0" />
                <geometry>
                    <mesh
                        filename="package://my_robot_urdf/meshes/arm_link_1_coco.STL" />
                </geometry>
                <material
                    name="">
                    <color
                        rgba="0.792156862745098 0.819607843137255 0.933333333333333 1" />
                </material>
            </visual>
            <collision>
                <origin
                    xyz="0 0 0"
                    rpy="0 0 0" />
                <geometry>
                    <mesh
                        filename="package://my_robot_urdf/meshes/arm_link_1_coco.STL" />
                </geometry>
            </collision>
        </link>
        <joint
            name="${prefix}joint_link_1_coco"
            type="revolute">
            <origin
                xyz="0 0 0.18"
                rpy="1.5708 0 0" />
            <parent
                link="${prefix}base_link_coco" />
            <child
                link="${prefix}arm_link_1_coco" />
            <axis
                xyz="0 1 0" />
            <limit
                lower="-3.1416"
                upper="3.1416"
                effort="0"
                velocity="0" />
        </joint>
        <link
            name="${prefix}arm_link_2_coco">
            <inertial>
                <origin
                    xyz="0.0252292801061356 0.315341966336714 0.119016776091288"
                    rpy="0 0 0" />
                <mass
                    value="29.9902849835083" />
                <inertia
                    ixx="2.0278918621324"
                    ixy="-0.156444807181449"
                    ixz="2.66331568201595E-17"
                    iyy="0.155884497994694"
                    iyz="2.4398292141135E-17"
                    izz="2.1168438189684" />
            </inertial>
            <visual>
                <origin
                    xyz="0 0 0"
                    rpy="0 0 0" />
                <geometry>
                    <mesh
                        filename="package://my_robot_urdf/meshes/arm_link_2_coco.STL" />
                </geometry>
                <material
                    name="">
                    <color
                        rgba="0.792156862745098 0.819607843137255 0.933333333333333 1" />
                </material>
            </visual>
            <collision>
                <origin
                    xyz="0 0 0"
                    rpy="0 0 0" />
                <geometry>
                    <mesh
                        filename="package://my_robot_urdf/meshes/arm_link_2_coco.STL" />
                </geometry>
            </collision>
        </link>
        <joint
            name="${prefix}joint_link_2_coco"
            type="revolute">
            <origin
                xyz="0.14579 0.33595 0.090292"
                rpy="0 0 0.082805" />
            <parent
                link="${prefix}arm_link_1_coco" />
            <child
                link="${prefix}arm_link_2_coco" />
            <axis
                xyz="0 0 1" />
            <limit
                lower="-3.1416"
                upper="3.1416"
                effort="0"
                velocity="0" />
        </joint>
        <link
            name="${prefix}arm_link_3_coco">
            <inertial>
                <origin
                    xyz="0.170027563293456 0.0889986484280518 -0.0663605481820072"
                    rpy="0 0 0" />
                <mass
                    value="16.1199771168543" />
                <inertia
                    ixx="0.137763861529296"
                    ixy="-0.0959483935903458"
                    ixz="-0.0167225971301647"
                    iyy="0.190812936291584"
                    iyz="-0.012987856550598"
                    izz="0.261074961271267" />
            </inertial>
            <visual>
                <origin
                    xyz="0 0 0"
                    rpy="0 0 0" />
                <geometry>
                    <mesh
                        filename="package://my_robot_urdf/meshes/arm_link_3_coco.STL" />
                </geometry>
                <material
                    name="">
                    <color
                        rgba="0.792156862745098 0.819607843137255 0.933333333333333 1" />
                </material>
            </visual>
            <collision>
                <origin
                    xyz="0 0 0"
                    rpy="0 0 0" />
                <geometry>
                    <mesh
                        filename="package://my_robot_urdf/meshes/arm_link_3_coco.STL" />
                </geometry>
            </collision>
        </link>
        <joint
            name="${prefix}joint_link_3_coco"
            type="revolute">
            <origin
                xyz="0.0017779 0.76236 0"
                rpy="0 0 -0.082805" />
            <parent
                link="${prefix}arm_link_2_coco" />
            <child
                link="${prefix}arm_link_3_coco" />
            <axis
                xyz="0 0 1" />
            <limit
                lower="-3.1416"
                upper="3.1416"
                effort="0"
                velocity="0" />
        </joint>
        <link
            name="${prefix}arm_link_4_coco">
            <inertial>
                <origin
                    xyz="0.227600947287535 0.0354202245742417 -0.00589018251913133"
                    rpy="0 0 0" />
                <mass
                    value="8.2144132017799" />
                <inertia
                    ixx="0.0518416725365333"
                    ixy="-0.0168710233275404"
                    ixz="1.62360283324883E-05"
                    iyy="0.164102263665489"
                    iyz="1.53545094184089E-06"
                    izz="0.160372113366996" />
            </inertial>
            <visual>
                <origin
                    xyz="0 0 0"
                    rpy="0 0 0" />
                <geometry>
                    <mesh
                        filename="package://my_robot_urdf/meshes/arm_link_4_coco.STL" />
                </geometry>
                <material
                    name="">
                    <color
                        rgba="0.792156862745098 0.819607843137255 0.933333333333333 1" />
                </material>
            </visual>
            <collision>
                <origin
                    xyz="0 0 0"
                    rpy="0 0 0" />
                <geometry>
                    <mesh
                        filename="package://my_robot_urdf/meshes/arm_link_4_coco.STL" />
                </geometry>
            </collision>
        </link>
        <joint
            name="${prefix}joint_link_4_coco"
            type="revolute">
            <origin
                xyz="0.34817 0.19918 -0.073652"
                rpy="0 0 0" />
            <parent
                link="${prefix}arm_link_3_coco" />
            <child
                link="${prefix}arm_link_4_coco" />
            <axis
                xyz="1 0 0" />
            <limit
                lower="-3.1416"
                upper="3.1416"
                effort="0"
                velocity="0" />
        </joint>
        <link
            name="${prefix}arm_link_5_coco">
            <inertial>
                <origin
                    xyz="0.074010927598714 0.00261570038501091 -0.0027964156486263"
                    rpy="0 0 0" />
                <mass
                    value="1.15468077380916" />
                <inertia
                    ixx="0.0024180307299129"
                    ixy="-7.71125501828711E-06"
                    ixz="6.55345310597883E-07"
                    iyy="0.00301389716175276"
                    iyz="9.01091984498959E-09"
                    izz="0.00180806969473038" />
            </inertial>
            <visual>
                <origin
                    xyz="0 0 0"
                    rpy="0 0 0" />
                <geometry>
                    <mesh
                        filename="package://my_robot_urdf/meshes/arm_link_5_coco.STL" />
                </geometry>
                <material
                    name="">
                    <color
                        rgba="0.792156862745098 0.819607843137255 0.933333333333333 1" />
                </material>
            </visual>
            <collision>
                <origin
                    xyz="0 0 0"
                    rpy="0 0 0" />
                <geometry>
                    <mesh
                        filename="package://my_robot_urdf/meshes/arm_link_5_coco.STL" />
                </geometry>
            </collision>
        </link>
        <joint
            name="${prefix}joint_link_5_coco"
            type="revolute">
            <origin
                xyz="0.50466 0.0656 0"
                rpy="0 0 0" />
            <parent
                link="${prefix}arm_link_4_coco" />
            <child
                link="${prefix}arm_link_5_coco" />
            <axis
                xyz="0 0 1" />
            <limit
                lower="-3.1416"
                upper="3.1416"
                effort="0"
                velocity="0" />
        </joint>
        <link
            name="${prefix}arm_link_6_coco">
            <inertial>
                <origin
                    xyz="-0.137111409069475 -0.00299185190530271 5.18333732646373E-05"
                    rpy="0 0 0" />
                <mass
                    value="1.15468077380916" />
                <inertia
                    ixx="0.0024180307299129"
                    ixy="-7.71125501828703E-06"
                    ixz="6.55345310596748E-07"
                    iyy="0.00301389716175276"
                    iyz="9.01091984524858E-09"
                    izz="0.00180806969473038" />
            </inertial>
            <visual>
                <origin
                    xyz="0 0 0"
                    rpy="0 0 0" />
                <geometry>
                    <mesh
                        filename="package://my_robot_urdf/meshes/arm_link_6_coco.STL" />
                </geometry>
                <material
                    name="">
                    <color
                        rgba="0.792156862745098 0.819607843137255 0.933333333333333 1" />
                </material>
            </visual>
            <collision>
                <origin
                    xyz="0 0 0"
                    rpy="0 0 0" />
                <geometry>
                    <mesh
                        filename="package://my_robot_urdf/meshes/arm_link_6_coco.STL" />
                </geometry>
            </collision>
        </link>
        <joint
            name="${prefix}arm_joint_6_coco"
            type="revolute">
            <origin
                xyz="0.085 0.00067738 -0.0028482"
                rpy="0 0 3.1416" />
            <parent
                link="${prefix}arm_link_5_coco" />
            <child
                link="${prefix}arm_link_6_coco" />
            <axis
                xyz="1 0 0" />
            <limit
                lower="-3.1416"
                upper="3.1416"
                effort="0"
                velocity="0" />
        </joint>
        <link
            name="${prefix}eef_link_1_coco">
            <inertial>
                <origin
                    xyz="9.2350714006928E-05 3.29649640917751E-11 -0.124708296392705"
                    rpy="0 0 0" />
                <mass
                    value="0.153320639401569" />
                <inertia
                    ixx="8.37120102622993E-05"
                    ixy="-9.18633973936465E-14"
                    ixz="-1.37052372054366E-07"
                    iyy="8.34124297032976E-05"
                    iyz="-1.79341480280052E-13"
                    izz="0.000136601285012746" />
            </inertial>
            <visual>
                <origin
                    xyz="0 0 0"
                    rpy="0 0 0" />
                <geometry>
                    <mesh
                        filename="package://my_robot_urdf/meshes/eef_link_1_coco.STL" />
                </geometry>
                <material
                    name="">
                    <color
                        rgba="0.792156862745098 0.819607843137255 0.933333333333333 1" />
                </material>
            </visual>
            <collision>
                <origin
                    xyz="0 0 0"
                    rpy="0 0 0" />
                <geometry>
                    <mesh
                        filename="package://my_robot_urdf/meshes/eef_link_1_coco.STL" />
                </geometry>
            </collision>
        </link>
        <joint
            name="${prefix}eef_joint_1_fixed_coco"
            type="fixed">
            <origin
                xyz="-0.14806 -0.0031425 -0.20975"
                rpy="3.1416 0 3.1416" />
            <parent
                link="${prefix}arm_link_6_coco" />
            <child
                link="${prefix}eef_link_1_coco" />
            <axis
                xyz="0 0 0" />
        </joint>
        <link
            name="${prefix}eef_link_2_coco">
            <inertial>
                <origin
                    xyz="2.22044604925031E-16 0 -0.0480792617128722"
                    rpy="0 0 0" />
                <mass
                    value="0.158859300753402" />
                <inertia
                    ixx="0.000192557897320206"
                    ixy="-4.15050256991767E-20"
                    ixz="-6.97605421409928E-20"
                    iyy="0.000149672253524412"
                    iyz="-7.66971505960171E-20"
                    izz="0.00016094527647324" />
            </inertial>
            <visual>
                <origin
                    xyz="0 0 0"
                    rpy="0 0 0" />
                <geometry>
                    <mesh
                        filename="package://my_robot_urdf/meshes/eef_link_2_coco.STL" />
                </geometry>
                <material
                    name="">
                    <color
                        rgba="0.792156862745098 0.819607843137255 0.933333333333333 1" />
                </material>
            </visual>
            <collision>
                <origin
                    xyz="0 0 0"
                    rpy="0 0 0" />
                <geometry>
                    <mesh
                        filename="package://my_robot_urdf/meshes/eef_link_2_coco.STL" />
                </geometry>
            </collision>
        </link>
        <joint
            name="${prefix}eef_joint_2_fixed_coco"
            type="fixed">
            <origin
                xyz="-0.14806 -0.0031425 0.13985"
                rpy="0 0 3.1416" />
            <parent
                link="${prefix}arm_link_6_coco" />
            <child
                link="${prefix}eef_link_2_coco" />
            <axis
                xyz="0 0 0" />
        </joint>
    </xacro:macro>
</robot>