<?xml version="1.0" encoding="utf-8"?>
<robot xmlns:xacro="http://www.ros.org/wiki/xacro" name="arm">
    <xacro:macro name="arm_coco" params="prefix parent_link xyz='0 0 0' rpy='0 0 0'">
        <link
            name="${prefix}base_link_coco">
            <inertial>
                <origin
                    xyz="-0.0764021530191944 2.71349348865524E-05 0.0792317455056668"
                    rpy="0 0 0" />
                <mass
                    value="33.7641312353281" />
                <inertia
                    ixx="0.388653917501998"
                    ixy="3.75787448655195E-18"
                    ixz="6.82570301647603E-05"
                    iyy="0.347678993710906"
                    iyz="8.89625811535709E-18"
                    izz="0.646698533818771" />
            </inertial>
            <visual>
                <origin
                    xyz="0 0 0"
                    rpy="0 0 0" />
                <geometry>
                    <mesh
                        filename="package://my_robot_urdf/meshes/base_link_coco.STL" />
                </geometry>
                <material
                    name="">
                    <color
                        rgba="0.792156862745098 0.819607843137255 0.933333333333333 1" />
                </material>
            </visual>
            <collision>
                <origin
                    xyz="0 0 0"
                    rpy="0 0 0" />
                <geometry>
                    <mesh
                        filename="package://my_robot_urdf/meshes/base_link_coco.STL" />
                </geometry>
            </collision>
        </link>
        <!-- Define the joint connecting this arm to the parent link -->
        <joint name="${prefix}base_joint_coco" type="fixed">
            <origin xyz="${xyz}" rpy="${rpy}" />
            <parent link="${parent_link}" />
            <child link="${prefix}base_link_coco" />
        </joint>
        <link
            name="${prefix}arm_link_1_coco">
            <inertial>
                <origin
                    xyz="0.0310954578647585 -0.00332496023117675 0.134341853376388"
                    rpy="0 0 0" />
                <mass
                    value="28.7973325809481" />
                <inertia
                    ixx="0.316024916828851"
                    ixy="-0.000189061034524887"
                    ixz="-0.0129236801369765"
                    iyy="0.322997369549128"
                    iyz="-0.000316914959622081"
                    izz="0.500692862333896" />
            </inertial>
            <visual>
                <origin
                    xyz="0 0 0"
                    rpy="0 0 0" />
                <geometry>
                    <mesh
                        filename="package://my_robot_urdf/meshes/arm_link_1_coco.STL" />
                </geometry>
                <material
                    name="">
                    <color
                        rgba="0.792156862745098 0.819607843137255 0.933333333333333 1" />
                </material>
            </visual>
            <collision>
                <origin
                    xyz="0 0 0"
                    rpy="0 0 0" />
                <geometry>
                    <mesh
                        filename="package://my_robot_urdf/meshes/arm_link_1_coco.STL" />
                </geometry>
            </collision>
        </link>
        <joint
            name="${prefix}joint_link_1_coco"
            type="revolute">
            <origin
                xyz="0 0 0.18"
                rpy="0 0 0" />
            <parent
                link="${prefix}base_link_coco" />
            <child
                link="${prefix}arm_link_1_coco" />
            <axis
                xyz="0 0 1" />
            <limit
                lower="-3.1416"
                upper="3.1416"
                effort="0"
                velocity="0" />
        </joint>
        <link
            name="${prefix}arm_link_2_coco">
            <inertial>
                <origin
                    xyz="-0.000939286587736787 0.316348210123726 0.119016776091287"
                    rpy="0 0 0" />
                <mass
                    value="29.9902849835083" />
                <inertia
                    ixx="2.04087599375796"
                    ixy="6.72038874095361E-18"
                    ixz="2.43431801579158E-17"
                    iyy="0.14290036636914"
                    iyz="1.09136139887468E-17"
                    izz="2.11684381896841" />
            </inertial>
            <visual>
                <origin
                    xyz="0 0 0"
                    rpy="0 0 0" />
                <geometry>
                    <mesh
                        filename="package://my_robot_urdf/meshes/arm_link_2_coco.STL" />
                </geometry>
                <material
                    name="">
                    <color
                        rgba="0.792156862745098 0.819607843137255 0.933333333333333 1" />
                </material>
            </visual>
            <collision>
                <origin
                    xyz="0 0 0"
                    rpy="0 0 0" />
                <geometry>
                    <mesh
                        filename="package://my_robot_urdf/meshes/arm_link_2_coco.STL" />
                </geometry>
            </collision>
        </link>
        <joint
            name="${prefix}joint_link_2_coco"
            type="revolute">
            <origin
                xyz="0.14579 -0.090292 0.33595"
                rpy="1.5708 0 0" />
            <parent
                link="${prefix}arm_link_1_coco" />
            <child
                link="${prefix}arm_link_2_coco" />
            <axis
                xyz="0 0 1" />
            <limit
                lower="-3.1416"
                upper="3.1416"
                effort="0"
                velocity="0" />
        </joint>
        <link
            name="${prefix}arm_link_3_coco">
            <inertial>
                <origin
                    xyz="-0.106966394959347 0.0865335610269826 0.0663605481820073"
                    rpy="0 0 0" />
                <mass
                    value="16.1199771168543" />
                <inertia
                    ixx="0.137763861529296"
                    ixy="0.0959483935903455"
                    ixz="-0.0167225971301647"
                    iyy="0.190812936291584"
                    iyz="0.012987856550598"
                    izz="0.261074961271267" />
            </inertial>
            <visual>
                <origin
                    xyz="0 0 0"
                    rpy="0 0 0" />
                <geometry>
                    <mesh
                        filename="package://my_robot_urdf/meshes/arm_link_3_coco.STL" />
                </geometry>
                <material
                    name="">
                    <color
                        rgba="0.792156862745098 0.819607843137255 0.933333333333333 1" />
                </material>
            </visual>
            <collision>
                <origin
                    xyz="0 0 0"
                    rpy="0 0 0" />
                <geometry>
                    <mesh
                        filename="package://my_robot_urdf/meshes/arm_link_3_coco.STL" />
                </geometry>
            </collision>
        </link>
        <joint
            name="${prefix}joint_link_3_coco"
            type="revolute">
            <origin
                xyz="0.0017779 0.76236 0"
                rpy="3.1416 0 3.1416" />
            <parent
                link="${prefix}arm_link_2_coco" />
            <child
                link="${prefix}arm_link_3_coco" />
            <axis
                xyz="0 0 -1" />
            <limit
                lower="-3.1416"
                upper="3.1416"
                effort="0"
                velocity="0" />
        </joint>
        <link
            name="${prefix}arm_link_4_coco">
            <inertial>
                <origin
                    xyz="0.00589018251913124 0.0329551371731716 0.164539778953426"
                    rpy="0 0 0" />
                <mass
                    value="8.2144132017799" />
                <inertia
                    ixx="0.160372113366996"
                    ixy="-1.53545094183617E-06"
                    ixz="-1.62360283324988E-05"
                    iyy="0.164102263665489"
                    iyz="-0.0168710233275404"
                    izz="0.0518416725365331" />
            </inertial>
            <visual>
                <origin
                    xyz="0 0 0"
                    rpy="0 0 0" />
                <geometry>
                    <mesh
                        filename="package://my_robot_urdf/meshes/arm_link_4_coco.STL" />
                </geometry>
                <material
                    name="">
                    <color
                        rgba="0.792156862745098 0.819607843137255 0.933333333333333 1" />
                </material>
            </visual>
            <collision>
                <origin
                    xyz="0 0 0"
                    rpy="0 0 0" />
                <geometry>
                    <mesh
                        filename="package://my_robot_urdf/meshes/arm_link_4_coco.STL" />
                </geometry>
            </collision>
        </link>
        <joint
            name="${prefix}joint_link_4_coco"
            type="revolute">
            <origin
                xyz="-0.34817 0.19918 0.073652"
                rpy="3.1416 -1.5708 3.1416" />
            <parent
                link="${prefix}arm_link_3_coco" />
            <child
                link="${prefix}arm_link_4_coco" />
            <axis
                xyz="0 0 1" />
            <limit
                lower="-3.1416"
                upper="3.1416"
                effort="0"
                velocity="0" />
        </joint>
        <link
            name="${prefix}arm_link_5_coco">
            <inertial>
                <origin
                    xyz="0.010949759264604 0.000150612983941256 -0.00279641564862637"
                    rpy="0 0 0" />
                <mass
                    value="1.15468077380916" />
                <inertia
                    ixx="0.0024180307299129"
                    ixy="-7.71125501828698E-06"
                    ixz="6.55345310597226E-07"
                    iyy="0.00301389716175276"
                    iyz="9.01091984503082E-09"
                    izz="0.00180806969473038" />
            </inertial>
            <visual>
                <origin
                    xyz="0 0 0"
                    rpy="0 0 0" />
                <geometry>
                    <mesh
                        filename="package://my_robot_urdf/meshes/arm_link_5_coco.STL" />
                </geometry>
                <material
                    name="">
                    <color
                        rgba="0.792156862745098 0.819607843137255 0.933333333333333 1" />
                </material>
            </visual>
            <collision>
                <origin
                    xyz="0 0 0"
                    rpy="0 0 0" />
                <geometry>
                    <mesh
                        filename="package://my_robot_urdf/meshes/arm_link_5_coco.STL" />
                </geometry>
            </collision>
        </link>
        <joint
            name="${prefix}joint_link_5_coco"
            type="revolute">
            <origin
                xyz="0 0.0656 0.50466"
                rpy="3.1416 -1.5708 0" />
            <parent
                link="${prefix}arm_link_4_coco" />
            <child
                link="${prefix}arm_link_5_coco" />
            <axis
                xyz="0 0 1" />
            <limit
                lower="-3.1416"
                upper="3.1416"
                effort="0"
                velocity="0" />
        </joint>
        <link
            name="${prefix}arm_link_6_coco">
            <inertial>
                <origin
                    xyz="-5.1833373264849E-05 0.000526764504232613 0.074050240735366"
                    rpy="0 0 0" />
                <mass
                    value="1.15468077380916" />
                <inertia
                    ixx="0.00180806969473038"
                    ixy="9.01091984507194E-09"
                    ixz="6.55345310597047E-07"
                    iyy="0.00301389716175276"
                    iyz="-7.71125501828711E-06"
                    izz="0.0024180307299129" />
            </inertial>
            <visual>
                <origin
                    xyz="0 0 0"
                    rpy="0 0 0" />
                <geometry>
                    <mesh
                        filename="package://my_robot_urdf/meshes/arm_link_6_coco.STL" />
                </geometry>
                <material
                    name="">
                    <color
                        rgba="0.792156862745098 0.819607843137255 0.933333333333333 1" />
                </material>
            </visual>
            <collision>
                <origin
                    xyz="0 0 0"
                    rpy="0 0 0" />
                <geometry>
                    <mesh
                        filename="package://my_robot_urdf/meshes/arm_link_6_coco.STL" />
                </geometry>
            </collision>
        </link>
        <joint
            name="${prefix}arm_joint_6_coco"
            type="revolute">
            <origin
                xyz="0.085 0.00067738 -0.0028482"
                rpy="0 1.5708 0" />
            <parent
                link="${prefix}arm_link_5_coco" />
            <child
                link="${prefix}arm_link_6_coco" />
            <axis
                xyz="0 0 -1" />
            <limit
                lower="-3.1416"
                upper="3.1416"
                effort="0"
                velocity="0" />
        </joint>
        <link
            name="${prefix}eef_link_1_coco">
            <inertial>
                <origin
                    xyz="3.29649640917751E-11 -9.235071400715E-05 -0.124708296392705"
                    rpy="0 0 0" />
                <mass
                    value="0.15332063940157" />
                <inertia
                    ixx="8.3412429703298E-05"
                    ixy="9.18634115356551E-14"
                    ixz="-1.79341490009726E-13"
                    iyy="8.37120102622999E-05"
                    iyz="1.37052372054436E-07"
                    izz="0.000136601285012748" />
            </inertial>
            <visual>
                <origin
                    xyz="0 0 0"
                    rpy="0 0 0" />
                <geometry>
                    <mesh
                        filename="package://my_robot_urdf/meshes/eef_link_1_coco.STL" />
                </geometry>
                <material
                    name="">
                    <color
                        rgba="0.792156862745098 0.819607843137255 0.933333333333333 1" />
                </material>
            </visual>
            <collision>
                <origin
                    xyz="0 0 0"
                    rpy="0 0 0" />
                <geometry>
                    <mesh
                        filename="package://my_robot_urdf/meshes/eef_link_1_coco.STL" />
                </geometry>
            </collision>
        </link>
        <joint
            name="${prefix}eef_joint_1_fixed_coco"
            type="fixed">
            <origin
                xyz="0.20975 0.00067738 0.085"
                rpy="-1.5708 0 -1.5708" />
            <parent
                link="${prefix}arm_link_6_coco" />
            <child
                link="${prefix}eef_link_1_coco" />
            <axis
                xyz="0 0 0" />
        </joint>
        <link
            name="${prefix}eef_link_2_coco">
            <inertial>
                <origin
                    xyz="0 0 -0.0480792617128722"
                    rpy="0 0 0" />
                <mass
                    value="0.158859300753402" />
                <inertia
                    ixx="0.000149672253524412"
                    ixy="-4.9614680881843E-21"
                    ixz="7.79229232056955E-22"
                    iyy="0.000192557897320206"
                    iyz="1.28004734861553E-20"
                    izz="0.00016094527647324" />
            </inertial>
            <visual>
                <origin
                    xyz="0 0 0"
                    rpy="0 0 0" />
                <geometry>
                    <mesh
                        filename="package://my_robot_urdf/meshes/eef_link_2_coco.STL" />
                </geometry>
                <material
                    name="">
                    <color
                        rgba="0.792156862745098 0.819607843137255 0.933333333333333 1" />
                </material>
            </visual>
            <collision>
                <origin
                    xyz="0 0 0"
                    rpy="0 0 0" />
                <geometry>
                    <mesh
                        filename="package://my_robot_urdf/meshes/eef_link_2_coco.STL" />
                </geometry>
            </collision>
        </link>
        <joint
            name="${prefix}eef_joint_2_fixed_coco"
            type="fixed">
            <origin
                xyz="-0.13985 0.00067738 0.085"
                rpy="-1.5708 0 1.5708" />
            <parent
                link="${prefix}arm_link_6_coco" />
            <child
                link="${prefix}eef_link_2_coco" />
            <axis
                xyz="0 0 0" />
        </joint>
    </xacro:macro>
</robot>