<?xml version="1.0" encoding="utf-8"?>
<robot xmlns:xacro="http://www.ros.org/wiki/xacro" name="arm">
  <xacro:macro name="arm_yuzi" params="prefix parent_link xyz='0 0 0' rpy='0 0 0'">
    <link
      name="${prefix}base_link_yuzi">
      <inertial>
        <origin
          xyz="-5.25107086452931E-18 -9.69114882893545E-18 0.131559716820544"
          rpy="0 0 0" />
        <mass
          value="13.926198063469" />
        <inertia
          ixx="0.150359375184122"
          ixy="6.0351097491869E-18"
          ixz="-1.94834723594448E-17"
          iyy="0.150359375184122"
          iyz="-1.44976161137733E-17"
          izz="0.11575755967506" />
      </inertial>
      <visual>
        <origin
          xyz="0 0 0"
          rpy="0 0 0" />
        <geometry>
          <mesh
            filename="package://my_robot_urdf/meshes/base_link_yuzi.STL" />
        </geometry>
        <material
          name="">
          <color
            rgba="0.792156862745098 0.819607843137255 0.933333333333333 1" />
        </material>
      </visual>
      <collision>
        <origin
          xyz="0 0 0"
          rpy="0 0 0" />
        <geometry>
          <mesh
            filename="package://my_robot_urdf/meshes/base_link_yuzi.STL" />
        </geometry>
      </collision>
    </link>
    <!-- Define the joint connecting this arm to the parent link -->
    <joint name="${prefix}base_joint_yuzi" type="fixed">
      <origin xyz="${xyz}" rpy="${rpy}" />
      <parent link="${parent_link}" />
      <child link="${prefix}base_link_yuzi" />
    </joint>
    <link
      name="${prefix}arm_link_1_yuzi">
      <inertial>
        <origin
          xyz="0.0393277653963038 1.00151935086465E-07 0.150866622191122"
          rpy="0 0 0" />
        <mass
          value="17.6840361237851" />
        <inertia
          ixx="0.387077403080444"
          ixy="3.67268000731293E-07"
          ixz="-0.0824473388415476"
          iyy="0.281535059283111"
          iyz="6.77341185639246E-08"
          izz="0.349932526197817" />
      </inertial>
      <visual>
        <origin
          xyz="0 0 0"
          rpy="0 0 0" />
        <geometry>
          <mesh
            filename="package://my_robot_urdf/meshes/arm_link_1_yuzi.STL" />
        </geometry>
        <material
          name="">
          <color
            rgba="0.780392156862745 0.8 0.788235294117647 1" />
        </material>
      </visual>
      <collision>
        <origin
          xyz="0 0 0"
          rpy="0 0 0" />
        <geometry>
          <mesh
            filename="package://my_robot_urdf/meshes/arm_link_1_yuzi.STL" />
        </geometry>
      </collision>
    </link>
    <joint
      name="${prefix}arm_joint_1_yuzi"
      type="revolute">
      <origin
        xyz="0 0 0.274"
        rpy="0 0 0" />
      <parent
        link="${prefix}base_link_yuzi" />
      <child
        link="${prefix}arm_link_1_yuzi" />
      <axis
        xyz="0 0 1" />
      <limit
        lower="-3.1416"
        upper="3.1416"
        effort="0"
        velocity="0" />
    </joint>
    <link
      name="${prefix}arm_link_2_yuzi">
      <inertial>
        <origin
          xyz="5.931859369257E-07 -0.202994951659398 -0.00270543986390563"
          rpy="0 0 0" />
        <mass
          value="21.695061095067" />
        <inertia
          ixx="0.29491156513822"
          ixy="2.31415083687633E-06"
          ixz="1.23997830829163E-09"
          iyy="0.0783160010403902"
          iyz="0.000394743850237622"
          izz="0.301877815458434" />
      </inertial>
      <visual>
        <origin
          xyz="0 0 0"
          rpy="0 0 0" />
        <geometry>
          <mesh
            filename="package://my_robot_urdf/meshes/arm_link_2_yuzi.STL" />
        </geometry>
        <material
          name="">
          <color
            rgba="0.780392156862745 0.8 0.788235294117647 1" />
        </material>
      </visual>
      <collision>
        <origin
          xyz="0 0 0"
          rpy="0 0 0" />
        <geometry>
          <mesh
            filename="package://my_robot_urdf/meshes/arm_link_2_yuzi.STL" />
        </geometry>
      </collision>
    </link>
    <joint
      name="${prefix}arm_joint_2_yuzi"
      type="revolute">
      <origin
        xyz="0.15 0 0.29"
        rpy="-1.5708 0 3.1416" />
      <parent
        link="${prefix}arm_link_1_yuzi" />
      <child
        link="${prefix}arm_link_2_yuzi" />
      <axis
        xyz="0 0 -1" />
      <limit
        lower="-1.5708"
        upper="1.5708"
        effort="0"
        velocity="0" />
    </joint>
    <link
      name="${prefix}arm_link_3_yuzi">
      <inertial>
        <origin
          xyz="0.000448863422053053 -0.0261515151771508 -0.00178825757800023"
          rpy="0 0 0" />
        <mass
          value="4.48725682214162" />
        <inertia
          ixx="0.00921991972060868"
          ixy="4.02687063686657E-19"
          ixz="-7.15729755686699E-35"
          iyy="0.0233991913614871"
          iyz="1.50053365905829E-35"
          izz="0.0219081787552183" />
      </inertial>
      <visual>
        <origin
          xyz="0 0 0"
          rpy="0 0 0" />
        <geometry>
          <mesh
            filename="package://my_robot_urdf/meshes/arm_link_3_yuzi.STL" />
        </geometry>
        <material
          name="">
          <color
            rgba="0.792156862745098 0.819607843137255 0.933333333333333 1" />
        </material>
      </visual>
      <collision>
        <origin
          xyz="0 0 0"
          rpy="0 0 0" />
        <geometry>
          <mesh
            filename="package://my_robot_urdf/meshes/arm_link_3_yuzi.STL" />
        </geometry>
      </collision>
    </link>
    <joint
      name="${prefix}arm_joint_3_yuzi"
      type="revolute">
      <origin
        xyz="0 -0.575 0"
        rpy="0 0 0" />
      <parent
        link="${prefix}arm_link_2_yuzi" />
      <child
        link="${prefix}arm_link_3_yuzi" />
      <axis
        xyz="0 0 -1" />
      <limit
        lower="-1.5708"
        upper="1.5708"
        effort="0"
        velocity="0" />
    </joint>
    <link
      name="${prefix}arm_link_4_yuzi">
      <inertial>
        <origin
          xyz="6.66133814775094E-16 0.000932919736385606 0.288902507196118"
          rpy="0 0 0" />
        <mass
          value="7.8906783291211" />
        <inertia
          ixx="0.0897241931118627"
          ixy="-2.23893475246992E-19"
          ixz="-9.51519221962284E-19"
          iyy="0.0881400417573612"
          iyz="-0.000989909842324874"
          izz="0.0169814358788831" />
      </inertial>
      <visual>
        <origin
          xyz="0 0 0"
          rpy="0 0 0" />
        <geometry>
          <mesh
            filename="package://my_robot_urdf/meshes/arm_link_4_yuzi.STL" />
        </geometry>
        <material
          name="">
          <color
            rgba="0.792156862745098 0.819607843137255 0.933333333333333 1" />
        </material>
      </visual>
      <collision>
        <origin
          xyz="0 0 0"
          rpy="0 0 0" />
        <geometry>
          <mesh
            filename="package://my_robot_urdf/meshes/arm_link_4_yuzi.STL" />
        </geometry>
      </collision>
    </link>
    <joint
      name="${prefix}arm_joint_4_yuzi"
      type="revolute">
      <origin
        xyz="-0.1295 -0.04 -0.003"
        rpy="1.5708 0 -1.5708" />
      <parent
        link="${prefix}arm_link_3_yuzi" />
      <child
        link="${prefix}arm_link_4_yuzi" />
      <axis
        xyz="0 0 1" />
      <limit
        lower="-3.1416"
        upper="3.1416"
        effort="0"
        velocity="0" />
    </joint>
    <link
      name="${prefix}arm_link_5_yuzi">
      <inertial>
        <origin
          xyz="-0.0209881134676554 -1.11622497689368E-07 -0.00829305633881015"
          rpy="0 0 0" />
        <mass
          value="0.684392926448249" />
        <inertia
          ixx="0.000641087602858553"
          ixy="-1.13848125275888E-09"
          ixz="0.000110196226559993"
          iyy="0.00118845959430424"
          iyz="8.1268868198354E-12"
          izz="0.0013177404399051" />
      </inertial>
      <visual>
        <origin
          xyz="0 0 0"
          rpy="0 0 0" />
        <geometry>
          <mesh
            filename="package://my_robot_urdf/meshes/arm_link_5_yuzi.STL" />
        </geometry>
        <material
          name="">
          <color
            rgba="0.792156862745098 0.819607843137255 0.933333333333333 1" />
        </material>
      </visual>
      <collision>
        <origin
          xyz="0 0 0"
          rpy="0 0 0" />
        <geometry>
          <mesh
            filename="package://my_robot_urdf/meshes/arm_link_5_yuzi.STL" />
        </geometry>
      </collision>
    </link>
    <joint
      name="${prefix}arm_joint_5_yuzi"
      type="revolute">
      <origin
        xyz="0 0 0.5455"
        rpy="-1.5708 1.5708 0" />
      <parent
        link="${prefix}arm_link_4_yuzi" />
      <child
        link="${prefix}arm_link_5_yuzi" />
      <axis
        xyz="0 0 1" />
      <limit
        lower="-1.5708"
        upper="1.5708"
        effort="0"
        velocity="0" />
    </joint>
    <link
      name="${prefix}arm_link_6_yuzi">
      <inertial>
        <origin
          xyz="-1.11022302462516E-15 1.66967134562768E-15 0.0364608960848188"
          rpy="0 0 0" />
        <mass
          value="0.190738563830904" />
        <inertia
          ixx="0.000165744627457126"
          ixy="2.87815384189059E-22"
          ixz="-1.96348501644814E-20"
          iyy="0.000161337003377479"
          iyz="8.04929607286269E-21"
          izz="8.21544962643498E-05" />
      </inertial>
      <visual>
        <origin
          xyz="0 0 0"
          rpy="0 0 0" />
        <geometry>
          <mesh
            filename="package://my_robot_urdf/meshes/arm_link_6_yuzi.STL" />
        </geometry>
        <material
          name="">
          <color
            rgba="0.792156862745098 0.819607843137255 0.933333333333333 1" />
        </material>
      </visual>
      <collision>
        <origin
          xyz="0 0 0"
          rpy="0 0 0" />
        <geometry>
          <mesh
            filename="package://my_robot_urdf/meshes/arm_link_6_yuzi.STL" />
        </geometry>
      </collision>
    </link>
    <joint
      name="${prefix}arm_joint_6_yuzi"
      type="revolute">
      <origin
        xyz="-0.085 0 0"
        rpy="-1.5708 0 1.5708" />
      <parent
        link="${prefix}arm_link_5_yuzi" />
      <child
        link="${prefix}arm_link_6_yuzi" />
      <axis
        xyz="0 0 1" />
      <limit
        lower="-3.1416"
        upper="3.1416"
        effort="0"
        velocity="0" />
    </joint>
    <link
      name="${prefix}eef_link_yuzi">
      <inertial>
        <origin
          xyz="-0.00215923528943862 -1.34441069388203E-17 -0.0685050835227634"
          rpy="0 0 0" />
        <mass
          value="0.190738563830904" />
        <inertia
          ixx="0.000165661665669484"
          ixy="6.02940705304147E-22"
          ixz="-2.63209119423623E-06"
          iyy="0.000161337003377479"
          iyz="1.01035149151913E-20"
          izz="8.22374580519918E-05" />
      </inertial>
      <visual>
        <origin
          xyz="0 0 0"
          rpy="0 0 0" />
        <geometry>
          <mesh
            filename="package://my_robot_urdf/meshes/eef_link_yuzi.STL" />
        </geometry>
        <material
          name="">
          <color
            rgba="0.792156862745098 0.819607843137255 0.933333333333333 1" />
        </material>
      </visual>
      <collision>
        <origin
          xyz="0 0 0"
          rpy="0 0 0" />
        <geometry>
          <mesh
            filename="package://my_robot_urdf/meshes/eef_link_yuzi.STL" />
        </geometry>
      </collision>
    </link>
    <joint
      name="${prefix}eef_joint_fixed_yuzi"
      type="fixed">
      <origin
        xyz="0 0 0.105"
        rpy="0 -0.031509 0" />
      <parent
        link="${prefix}arm_link_6_yuzi" />
      <child
        link="${prefix}eef_link_yuzi" />
      <axis
        xyz="0 0 0" />
    </joint>
  </xacro:macro>
</robot>