<?xml version="1.0" ?>
<!-- =================================================================================== -->
<!-- |    This document was autogenerated by xacro from robot.xacro                    | -->
<!-- |    EDITING THIS FILE BY HAND IS NOT RECOMMENDED                                 | -->
<!-- =================================================================================== -->
<robot name="my_robot">
  <link name="main_workbench">
    <inertial>
      <origin rpy="0 0 0" xyz="0 0 0.05"/>
      <mass value="1000.0"/>
      <inertia ixx="100" ixy="0" ixz="0" iyy="100" iyz="0" izz="100"/>
    </inertial>
    <visual>
      <origin rpy="0 0 0" xyz="0 0 0.05"/>
      <geometry>
        <box size="2 4 0.1"/>
      </geometry>
      <material name="grey">
        <color rgba="0.5 0.5 0.5 1"/>
        <!-- Workbench color -->
      </material>
    </visual>
    <collision>
      <origin rpy="0 0 0" xyz="0 0 0.05"/>
      <geometry>
        <box size="2 4 0.1"/>
      </geometry>
    </collision>
  </link>
  <link name="main_workbench_2">
    <inertial>
      <origin rpy="0 0 0" xyz="0 0 0.3"/>
      <mass value="1000.0"/>
      <inertia ixx="100" ixy="0" ixz="0" iyy="100" iyz="0" izz="100"/>
    </inertial>
    <visual>
      <origin rpy="0 0 0" xyz="0 0 0.3"/>
      <geometry>
        <box size="2 4 0.6"/>
      </geometry>
      <material name="grey">
        <color rgba="0.5 0.5 0.5 1"/>
        <!-- Workbench color -->
      </material>
    </visual>
    <collision>
      <origin rpy="0 0 0" xyz="0 0 0.3"/>
      <geometry>
        <box size="2 4 0.6"/>
      </geometry>
    </collision>
  </link>
  <!-- Main body link (central base link) -->
  <link name="central_base_link">
    <origin rpy="0 0 0" xyz="0 0 1.5"/>
    <!-- Adjusted to be above the workbench -->
  </link>
  <!-- Connect each workbench to the central base link with a fixed joint -->
  <joint name="base_to_workbench_1_joint" type="fixed">
    <parent link="central_base_link"/>
    <child link="main_workbench"/>
    <origin rpy="0 0 0" xyz="0 0 0"/>
    <!-- Adjust this origin as needed -->
  </joint>
  <joint name="base_to_workbench_2_joint" type="fixed">
    <parent link="central_base_link"/>
    <child link="main_workbench_2"/>
    <origin rpy="0 0 0" xyz="2.0 0 0"/>
    <!-- Adjust this origin as needed -->
  </joint>
  <!-- Define the base link of the arm -->
  <link name="left_base_link">
    <inertial>
      <origin rpy="0 0 0" xyz="0 1 0.1"/>
      <mass value="33.891578448587"/>
      <inertia ixx="0.562042604088221" ixy="-9.14376784490416E-12" ixz="0.00403961419511076" iyy="0.970694427805805" iyz="-7.30601560182848E-12" izz="1.29713482615658"/>
    </inertial>
    <visual>
      <origin rpy="0 0 0" xyz="0 0 0"/>
      <geometry>
        <mesh filename="package://my_robot_urdf/meshes/base_link.STL"/>
      </geometry>
      <material name="">
        <color rgba="0.152941176470588 0 0.117647058823529 1"/>
      </material>
    </visual>
    <collision>
      <origin rpy="0 0 0" xyz="0 0 0"/>
      <geometry>
        <mesh filename="package://my_robot_urdf/meshes/base_link.STL"/>
      </geometry>
    </collision>
  </link>
  <!-- Define the joint connecting this arm to the parent link -->
  <joint name="left_base_joint" type="fixed">
    <origin rpy="0 0 0" xyz="0 1 0.1"/>
    <parent link="central_base_link"/>
    <child link="left_base_link"/>
  </joint>
  <link name="left_arm_link_1">
    <inertial>
      <origin rpy="0 0 0" xyz="0.0416589398280025 -3.68988089329334E-05 0.19712083516126"/>
      <mass value="26.7048266497369"/>
      <inertia ixx="0.495499615132855" ixy="-0.0102760504758245" ixz="-0.0600935399650257" iyy="0.766768677077223" iyz="-0.0115358881770517" izz="0.604967931690783"/>
    </inertial>
    <visual>
      <origin rpy="0 0 0" xyz="0 0 0"/>
      <geometry>
        <mesh filename="package://my_robot_urdf/meshes/arm_link_1.STL"/>
      </geometry>
      <material name="">
        <color rgba="1 0.309803921568627 0.309803921568627 1"/>
      </material>
    </visual>
    <collision>
      <origin rpy="0 0 0" xyz="0 0 0"/>
      <geometry>
        <mesh filename="package://my_robot_urdf/meshes/arm_link_1.STL"/>
      </geometry>
    </collision>
  </link>
  <joint name="left_arm_joint_1" type="revolute">
    <origin rpy="0 0 0" xyz="0 0 0.234000000000013"/>
    <parent link="left_base_link"/>
    <child link="left_arm_link_1"/>
    <axis xyz="0 0 1"/>
    <limit effort="0" lower="-3.1416" upper="3.1416" velocity="0"/>
  </joint>
  <link name="left_arm_link_2">
    <inertial>
      <origin rpy="0 0 0" xyz="-0.290203503422467 0.000258724363916829 0.0707589768311214"/>
      <mass value="14.3270690802686"/>
      <inertia ixx="0.0504590836189902" ixy="4.64678003354567E-05" ixz="0.0137202067906074" iyy="0.848873613210201" iyz="-0.000175299197197552" izz="0.874803778149419"/>
    </inertial>
    <visual>
      <origin rpy="0 0 0" xyz="0 0 0"/>
      <geometry>
        <mesh filename="package://my_robot_urdf/meshes/arm_link_2.STL"/>
      </geometry>
      <material name="">
        <color rgba="0.792156862745098 0.819607843137255 0.933333333333333 1"/>
      </material>
    </visual>
    <collision>
      <origin rpy="0 0 0" xyz="0 0 0"/>
      <geometry>
        <mesh filename="package://my_robot_urdf/meshes/arm_link_2.STL"/>
      </geometry>
    </collision>
  </link>
  <joint name="left_arm_joint_2" type="revolute">
    <origin rpy="1.5707963267949 0 0" xyz="0.150000000000002 -0.1375 0.265"/>
    <parent link="left_arm_link_1"/>
    <child link="left_arm_link_2"/>
    <axis xyz="0 0 1"/>
    <limit effort="0" lower="-3.1416" upper="3.1416" velocity="0"/>
  </joint>
  <link name="left_arm_link_3">
    <inertial>
      <origin rpy="0 0 0" xyz="0.0664637155357432 0.0362614171159604 0.123132908024542"/>
      <mass value="27.1450417424437"/>
      <inertia ixx="0.420912669748457" ixy="-0.0211648441841247" ixz="-0.00675660536457725" iyy="0.344868303293538" iyz="0.00338242702861573" izz="0.473964503565446"/>
    </inertial>
    <visual>
      <origin rpy="0 0 0" xyz="0 0 0"/>
      <geometry>
        <mesh filename="package://my_robot_urdf/meshes/arm_link_3.STL"/>
      </geometry>
      <material name="">
        <color rgba="0.792156862745098 0.819607843137255 0.933333333333333 1"/>
      </material>
    </visual>
    <collision>
      <origin rpy="0 0 0" xyz="0 0 0"/>
      <geometry>
        <mesh filename="package://my_robot_urdf/meshes/arm_link_3.STL"/>
      </geometry>
    </collision>
  </link>
  <joint name="left_arm_joint_3" type="continuous">
    <origin rpy="3.14159265358979 0 3.14159265358979" xyz="-0.700000000000001 0 0"/>
    <parent link="left_arm_link_2"/>
    <child link="left_arm_link_3"/>
    <axis xyz="0 0 -1"/>
    <limit effort="0" lower="-3.1416" upper="3.1416" velocity="0"/>
  </joint>
  <link name="left_arm_link_4">
    <inertial>
      <origin rpy="0 0 0" xyz="5.19381656460816E-07 4.95817308893837E-07 0.338893744219759"/>
      <mass value="7.96664349020365"/>
      <inertia ixx="0.223048843574734" ixy="-0.000166072999280483" ixz="4.33220175839122E-07" iyy="0.215976713293833" iyz="-3.48765154255128E-07" izz="0.0300827685994122"/>
    </inertial>
    <visual>
      <origin rpy="0 0 0" xyz="0 0 0"/>
      <geometry>
        <mesh filename="package://my_robot_urdf/meshes/arm_link_4.STL"/>
      </geometry>
      <material name="">
        <color rgba="0.792156862745098 0.819607843137255 0.933333333333333 1"/>
      </material>
    </visual>
    <collision>
      <origin rpy="0 0 0" xyz="0 0 0"/>
      <geometry>
        <mesh filename="package://my_robot_urdf/meshes/arm_link_4.STL"/>
      </geometry>
    </collision>
  </link>
  <joint name="left_arm_joint_4" type="revolute">
    <origin rpy="1.5707963267949 0 3.14159265358979" xyz="0.115 0.289996513803296 0.11"/>
    <parent link="left_arm_link_3"/>
    <child link="left_arm_link_4"/>
    <axis xyz="0 0 1"/>
    <limit effort="0" lower="-3.1416" upper="3.1416" velocity="0"/>
  </joint>
  <link name="left_arm_link_5">
    <inertial>
      <origin rpy="0 0 0" xyz="-0.00224018993807718 -7.93515697594671E-10 -4.63650767085211E-10"/>
      <mass value="0.961734748124672"/>
      <inertia ixx="0.00154678090917305" ixy="8.85889008790739E-10" ixz="1.41969821668856E-11" iyy="0.00143991315628678" iyz="9.91727417863987E-10" izz="0.00165625576362529"/>
    </inertial>
    <visual>
      <origin rpy="0 0 0" xyz="0 0 0"/>
      <geometry>
        <mesh filename="package://my_robot_urdf/meshes/arm_link_5.STL"/>
      </geometry>
      <material name="">
        <color rgba="0.792156862745098 0.819607843137255 0.933333333333333 1"/>
      </material>
    </visual>
    <collision>
      <origin rpy="0 0 0" xyz="0 0 0"/>
      <geometry>
        <mesh filename="package://my_robot_urdf/meshes/arm_link_5.STL"/>
      </geometry>
    </collision>
  </link>
  <joint name="left_arm_joint_5" type="revolute">
    <origin rpy="1.5707963267949 0 0" xyz="0 0 0.510003486196704"/>
    <parent link="left_arm_link_4"/>
    <child link="left_arm_link_5"/>
    <axis xyz="0 0 1"/>
    <limit effort="0" lower="-4.7124" upper="1.5708" velocity="0"/>
  </joint>
  <link name="left_arm_link_6">
    <inertial>
      <origin rpy="0 0 0" xyz="2.47238263195726E-08 2.0518347576548E-09 0.052725963344278"/>
      <mass value="0.288779624800079"/>
      <inertia ixx="0.000386925186804297" ixy="-2.51402341445703E-12" ixz="-3.11942429904297E-13" iyy="0.000386925215104185" iyz="-2.74312353784785E-14" izz="0.000212753902483572"/>
    </inertial>
    <visual>
      <origin rpy="0 0 0" xyz="0 0 0"/>
      <geometry>
        <mesh filename="package://my_robot_urdf/meshes/arm_link_6.STL"/>
      </geometry>
      <material name="">
        <color rgba="0.792156862745098 0.819607843137255 0.933333333333333 1"/>
      </material>
    </visual>
    <collision>
      <origin rpy="0 0 0" xyz="0 0 0"/>
      <geometry>
        <mesh filename="package://my_robot_urdf/meshes/arm_link_6.STL"/>
      </geometry>
    </collision>
  </link>
  <joint name="left_arm_joint_6" type="revolute">
    <origin rpy="-1.5707963267949 0 -1.5707963267949" xyz="0.0450000000000004 0 0"/>
    <parent link="left_arm_link_5"/>
    <child link="left_arm_link_6"/>
    <axis xyz="0 0 1"/>
    <limit effort="0" lower="-3.1416" upper="3.1416" velocity="0"/>
  </joint>
  <link name="left_eef_link">
    <inertial>
      <origin rpy="0 0 0" xyz="-9.30830701406649E-09 -4.47423127714064E-09 -0.0188761945416884"/>
      <mass value="5.46782575492837"/>
      <inertia ixx="0.0365076087226209" ixy="-1.69594623176887E-09" ixz="2.84396742647187E-09" iyy="0.0365076302641158" iyz="1.3669924295319E-09" izz="0.0627860547898383"/>
    </inertial>
    <visual>
      <origin rpy="0 0 0" xyz="0 0 0"/>
      <geometry>
        <mesh filename="package://my_robot_urdf/meshes/eef_link.STL"/>
      </geometry>
      <material name="">
        <color rgba="0.792156862745098 0.819607843137255 0.933333333333333 1"/>
      </material>
    </visual>
    <collision>
      <origin rpy="0 0 0" xyz="0 0 0"/>
      <geometry>
        <mesh filename="package://my_robot_urdf/meshes/eef_link.STL"/>
      </geometry>
    </collision>
  </link>
  <joint name="left_eef_link_fixed" type="fixed">
    <origin rpy="3.14159265358979 0 3.14159265358979" xyz="0 0 0.145"/>
    <parent link="left_arm_link_6"/>
    <child link="left_eef_link"/>
    <axis xyz="0 0 0"/>
  </joint>
  <link name="left_eef_jaw_1">
    <inertial>
      <origin rpy="0 0 0" xyz="0.0869730343447335 -0.02 0.0799489474646907"/>
      <mass value="0.672155087926634"/>
      <inertia ixx="0.00170709281582639" ixy="-2.10297489845672E-19" ixz="-0.000828153130362926" iyy="0.00264620439405273" iyz="-1.13884847286996E-19" izz="0.00111534333500677"/>
    </inertial>
    <visual>
      <origin rpy="0 0 0" xyz="0 0 0"/>
      <geometry>
        <mesh filename="package://my_robot_urdf/meshes/eef_jaw_1.STL"/>
      </geometry>
      <material name="">
        <color rgba="0.792156862745098 0.819607843137255 0.933333333333333 1"/>
      </material>
    </visual>
    <collision>
      <origin rpy="0 0 0" xyz="0 0 0"/>
      <geometry>
        <mesh filename="package://my_robot_urdf/meshes/eef_jaw_1.STL"/>
      </geometry>
    </collision>
  </link>
  <joint name="left_eef_jaw_1_joint_fixed" type="fixed">
    <origin rpy="3.14159265358979 0 0" xyz="-0.222284161474005 -0.0199999999999985 -0.0299999999999994"/>
    <parent link="left_eef_link"/>
    <child link="left_eef_jaw_1"/>
    <axis xyz="0 0 0"/>
  </joint>
  <link name="left_eef_jaw_2">
    <inertial>
      <origin rpy="0 0 0" xyz="0.0869730343447341 0.02 -0.0799489474646903"/>
      <mass value="0.672155087926635"/>
      <inertia ixx="0.00170709281582639" ixy="-5.6339619860202E-19" ixz="0.000828153130362932" iyy="0.00264620439405273" iyz="3.28558952421928E-19" izz="0.00111534333500678"/>
    </inertial>
    <visual>
      <origin rpy="0 0 0" xyz="0 0 0"/>
      <geometry>
        <mesh filename="package://my_robot_urdf/meshes/eef_jaw_2.STL"/>
      </geometry>
      <material name="">
        <color rgba="0.792156862745098 0.819607843137255 0.933333333333333 1"/>
      </material>
    </visual>
    <collision>
      <origin rpy="0 0 0" xyz="0 0 0"/>
      <geometry>
        <mesh filename="package://my_robot_urdf/meshes/eef_jaw_2.STL"/>
      </geometry>
    </collision>
  </link>
  <joint name="left_eef_jaw_2_joint_fixed" type="fixed">
    <origin rpy="0 0 3.14159265358979" xyz="0.222284161474005 0.0200000000000028 -0.0300000000000008"/>
    <parent link="left_eef_link"/>
    <child link="left_eef_jaw_2"/>
    <axis xyz="0 0 0"/>
  </joint>
  <link name="left_eef_jaw_3">
    <inertial>
      <origin rpy="0 0 0" xyz="0.0869730343447339 0.0199999999999998 -0.0799489474646904"/>
      <mass value="0.672155087926635"/>
      <inertia ixx="0.00170709281582639" ixy="1.22645739197657E-18" ixz="0.000828153130362931" iyy="0.00264620439405273" iyz="-2.65524845194663E-18" izz="0.00111534333500678"/>
    </inertial>
    <visual>
      <origin rpy="0 0 0" xyz="0 0 0"/>
      <geometry>
        <mesh filename="package://my_robot_urdf/meshes/eef_jaw_3.STL"/>
      </geometry>
      <material name="">
        <color rgba="0.792156862745098 0.819607843137255 0.933333333333333 1"/>
      </material>
    </visual>
    <collision>
      <origin rpy="0 0 0" xyz="0 0 0"/>
      <geometry>
        <mesh filename="package://my_robot_urdf/meshes/eef_jaw_3.STL"/>
      </geometry>
    </collision>
  </link>
  <joint name="left_eef_jaw_3_joint_fixed" type="fixed">
    <origin rpy="0 0 1.5707963267949" xyz="0.02 -0.222284161474003 -0.03"/>
    <parent link="left_eef_link"/>
    <child link="left_eef_jaw_3"/>
    <axis xyz="0 0 0"/>
  </joint>
  <link name="left_eef_jaw_4">
    <inertial>
      <origin rpy="0 0 0" xyz="0.0869730343447339 0.02 -0.0799489474646904"/>
      <mass value="0.672155087926635"/>
      <inertia ixx="0.00170709281582639" ixy="-7.21958594590805E-19" ixz="0.00082815313036293" iyy="0.00264620439405273" iyz="3.18822450133064E-18" izz="0.00111534333500678"/>
    </inertial>
    <visual>
      <origin rpy="0 0 0" xyz="0 0 0"/>
      <geometry>
        <mesh filename="package://my_robot_urdf/meshes/eef_jaw_4.STL"/>
      </geometry>
      <material name="">
        <color rgba="0.792156862745098 0.819607843137255 0.933333333333333 1"/>
      </material>
    </visual>
    <collision>
      <origin rpy="0 0 0" xyz="0 0 0"/>
      <geometry>
        <mesh filename="package://my_robot_urdf/meshes/eef_jaw_4.STL"/>
      </geometry>
    </collision>
  </link>
  <joint name="left_eef_jaw_4_joint_fixed" type="fixed">
    <origin rpy="0 0 -1.5707963267949" xyz="-0.0200000000000002 0.222284161474006 -0.0299999999999999"/>
    <parent link="left_eef_link"/>
    <child link="left_eef_jaw_4"/>
    <axis xyz="0 0 0"/>
  </joint>
  <!-- Define the base link of the arm -->
  <link name="right_base_link">
    <inertial>
      <origin rpy="0 0 0" xyz="0 -1 0.1"/>
      <mass value="33.891578448587"/>
      <inertia ixx="0.562042604088221" ixy="-9.14376784490416E-12" ixz="0.00403961419511076" iyy="0.970694427805805" iyz="-7.30601560182848E-12" izz="1.29713482615658"/>
    </inertial>
    <visual>
      <origin rpy="0 0 0" xyz="0 0 0"/>
      <geometry>
        <mesh filename="package://my_robot_urdf/meshes/base_link.STL"/>
      </geometry>
      <material name="">
        <color rgba="0.152941176470588 0 0.117647058823529 1"/>
      </material>
    </visual>
    <collision>
      <origin rpy="0 0 0" xyz="0 0 0"/>
      <geometry>
        <mesh filename="package://my_robot_urdf/meshes/base_link.STL"/>
      </geometry>
    </collision>
  </link>
  <!-- Define the joint connecting this arm to the parent link -->
  <joint name="right_base_joint" type="fixed">
    <origin rpy="0 0 0" xyz="0 -1 0.1"/>
    <parent link="central_base_link"/>
    <child link="right_base_link"/>
  </joint>
  <link name="right_arm_link_1">
    <inertial>
      <origin rpy="0 0 0" xyz="0.0416589398280025 -3.68988089329334E-05 0.19712083516126"/>
      <mass value="26.7048266497369"/>
      <inertia ixx="0.495499615132855" ixy="-0.0102760504758245" ixz="-0.0600935399650257" iyy="0.766768677077223" iyz="-0.0115358881770517" izz="0.604967931690783"/>
    </inertial>
    <visual>
      <origin rpy="0 0 0" xyz="0 0 0"/>
      <geometry>
        <mesh filename="package://my_robot_urdf/meshes/arm_link_1.STL"/>
      </geometry>
      <material name="">
        <color rgba="1 0.309803921568627 0.309803921568627 1"/>
      </material>
    </visual>
    <collision>
      <origin rpy="0 0 0" xyz="0 0 0"/>
      <geometry>
        <mesh filename="package://my_robot_urdf/meshes/arm_link_1.STL"/>
      </geometry>
    </collision>
  </link>
  <joint name="right_arm_joint_1" type="revolute">
    <origin rpy="0 0 0" xyz="0 0 0.234000000000013"/>
    <parent link="right_base_link"/>
    <child link="right_arm_link_1"/>
    <axis xyz="0 0 1"/>
    <limit effort="0" lower="-3.1416" upper="3.1416" velocity="0"/>
  </joint>
  <link name="right_arm_link_2">
    <inertial>
      <origin rpy="0 0 0" xyz="-0.290203503422467 0.000258724363916829 0.0707589768311214"/>
      <mass value="14.3270690802686"/>
      <inertia ixx="0.0504590836189902" ixy="4.64678003354567E-05" ixz="0.0137202067906074" iyy="0.848873613210201" iyz="-0.000175299197197552" izz="0.874803778149419"/>
    </inertial>
    <visual>
      <origin rpy="0 0 0" xyz="0 0 0"/>
      <geometry>
        <mesh filename="package://my_robot_urdf/meshes/arm_link_2.STL"/>
      </geometry>
      <material name="">
        <color rgba="0.792156862745098 0.819607843137255 0.933333333333333 1"/>
      </material>
    </visual>
    <collision>
      <origin rpy="0 0 0" xyz="0 0 0"/>
      <geometry>
        <mesh filename="package://my_robot_urdf/meshes/arm_link_2.STL"/>
      </geometry>
    </collision>
  </link>
  <joint name="right_arm_joint_2" type="revolute">
    <origin rpy="1.5707963267949 0 0" xyz="0.150000000000002 -0.1375 0.265"/>
    <parent link="right_arm_link_1"/>
    <child link="right_arm_link_2"/>
    <axis xyz="0 0 1"/>
    <limit effort="0" lower="-3.1416" upper="3.1416" velocity="0"/>
  </joint>
  <link name="right_arm_link_3">
    <inertial>
      <origin rpy="0 0 0" xyz="0.0664637155357432 0.0362614171159604 0.123132908024542"/>
      <mass value="27.1450417424437"/>
      <inertia ixx="0.420912669748457" ixy="-0.0211648441841247" ixz="-0.00675660536457725" iyy="0.344868303293538" iyz="0.00338242702861573" izz="0.473964503565446"/>
    </inertial>
    <visual>
      <origin rpy="0 0 0" xyz="0 0 0"/>
      <geometry>
        <mesh filename="package://my_robot_urdf/meshes/arm_link_3.STL"/>
      </geometry>
      <material name="">
        <color rgba="0.792156862745098 0.819607843137255 0.933333333333333 1"/>
      </material>
    </visual>
    <collision>
      <origin rpy="0 0 0" xyz="0 0 0"/>
      <geometry>
        <mesh filename="package://my_robot_urdf/meshes/arm_link_3.STL"/>
      </geometry>
    </collision>
  </link>
  <joint name="right_arm_joint_3" type="continuous">
    <origin rpy="3.14159265358979 0 3.14159265358979" xyz="-0.700000000000001 0 0"/>
    <parent link="right_arm_link_2"/>
    <child link="right_arm_link_3"/>
    <axis xyz="0 0 -1"/>
    <limit effort="0" lower="-3.1416" upper="3.1416" velocity="0"/>
  </joint>
  <link name="right_arm_link_4">
    <inertial>
      <origin rpy="0 0 0" xyz="5.19381656460816E-07 4.95817308893837E-07 0.338893744219759"/>
      <mass value="7.96664349020365"/>
      <inertia ixx="0.223048843574734" ixy="-0.000166072999280483" ixz="4.33220175839122E-07" iyy="0.215976713293833" iyz="-3.48765154255128E-07" izz="0.0300827685994122"/>
    </inertial>
    <visual>
      <origin rpy="0 0 0" xyz="0 0 0"/>
      <geometry>
        <mesh filename="package://my_robot_urdf/meshes/arm_link_4.STL"/>
      </geometry>
      <material name="">
        <color rgba="0.792156862745098 0.819607843137255 0.933333333333333 1"/>
      </material>
    </visual>
    <collision>
      <origin rpy="0 0 0" xyz="0 0 0"/>
      <geometry>
        <mesh filename="package://my_robot_urdf/meshes/arm_link_4.STL"/>
      </geometry>
    </collision>
  </link>
  <joint name="right_arm_joint_4" type="revolute">
    <origin rpy="1.5707963267949 0 3.14159265358979" xyz="0.115 0.289996513803296 0.11"/>
    <parent link="right_arm_link_3"/>
    <child link="right_arm_link_4"/>
    <axis xyz="0 0 1"/>
    <limit effort="0" lower="-3.1416" upper="3.1416" velocity="0"/>
  </joint>
  <link name="right_arm_link_5">
    <inertial>
      <origin rpy="0 0 0" xyz="-0.00224018993807718 -7.93515697594671E-10 -4.63650767085211E-10"/>
      <mass value="0.961734748124672"/>
      <inertia ixx="0.00154678090917305" ixy="8.85889008790739E-10" ixz="1.41969821668856E-11" iyy="0.00143991315628678" iyz="9.91727417863987E-10" izz="0.00165625576362529"/>
    </inertial>
    <visual>
      <origin rpy="0 0 0" xyz="0 0 0"/>
      <geometry>
        <mesh filename="package://my_robot_urdf/meshes/arm_link_5.STL"/>
      </geometry>
      <material name="">
        <color rgba="0.792156862745098 0.819607843137255 0.933333333333333 1"/>
      </material>
    </visual>
    <collision>
      <origin rpy="0 0 0" xyz="0 0 0"/>
      <geometry>
        <mesh filename="package://my_robot_urdf/meshes/arm_link_5.STL"/>
      </geometry>
    </collision>
  </link>
  <joint name="right_arm_joint_5" type="revolute">
    <origin rpy="1.5707963267949 0 0" xyz="0 0 0.510003486196704"/>
    <parent link="right_arm_link_4"/>
    <child link="right_arm_link_5"/>
    <axis xyz="0 0 1"/>
    <limit effort="0" lower="-4.7124" upper="1.5708" velocity="0"/>
  </joint>
  <link name="right_arm_link_6">
    <inertial>
      <origin rpy="0 0 0" xyz="2.47238263195726E-08 2.0518347576548E-09 0.052725963344278"/>
      <mass value="0.288779624800079"/>
      <inertia ixx="0.000386925186804297" ixy="-2.51402341445703E-12" ixz="-3.11942429904297E-13" iyy="0.000386925215104185" iyz="-2.74312353784785E-14" izz="0.000212753902483572"/>
    </inertial>
    <visual>
      <origin rpy="0 0 0" xyz="0 0 0"/>
      <geometry>
        <mesh filename="package://my_robot_urdf/meshes/arm_link_6.STL"/>
      </geometry>
      <material name="">
        <color rgba="0.792156862745098 0.819607843137255 0.933333333333333 1"/>
      </material>
    </visual>
    <collision>
      <origin rpy="0 0 0" xyz="0 0 0"/>
      <geometry>
        <mesh filename="package://my_robot_urdf/meshes/arm_link_6.STL"/>
      </geometry>
    </collision>
  </link>
  <joint name="right_arm_joint_6" type="revolute">
    <origin rpy="-1.5707963267949 0 -1.5707963267949" xyz="0.0450000000000004 0 0"/>
    <parent link="right_arm_link_5"/>
    <child link="right_arm_link_6"/>
    <axis xyz="0 0 1"/>
    <limit effort="0" lower="-3.1416" upper="3.1416" velocity="0"/>
  </joint>
  <link name="right_eef_link">
    <inertial>
      <origin rpy="0 0 0" xyz="-9.30830701406649E-09 -4.47423127714064E-09 -0.0188761945416884"/>
      <mass value="5.46782575492837"/>
      <inertia ixx="0.0365076087226209" ixy="-1.69594623176887E-09" ixz="2.84396742647187E-09" iyy="0.0365076302641158" iyz="1.3669924295319E-09" izz="0.0627860547898383"/>
    </inertial>
    <visual>
      <origin rpy="0 0 0" xyz="0 0 0"/>
      <geometry>
        <mesh filename="package://my_robot_urdf/meshes/eef_link.STL"/>
      </geometry>
      <material name="">
        <color rgba="0.792156862745098 0.819607843137255 0.933333333333333 1"/>
      </material>
    </visual>
    <collision>
      <origin rpy="0 0 0" xyz="0 0 0"/>
      <geometry>
        <mesh filename="package://my_robot_urdf/meshes/eef_link.STL"/>
      </geometry>
    </collision>
  </link>
  <joint name="right_eef_link_fixed" type="fixed">
    <origin rpy="3.14159265358979 0 3.14159265358979" xyz="0 0 0.145"/>
    <parent link="right_arm_link_6"/>
    <child link="right_eef_link"/>
    <axis xyz="0 0 0"/>
  </joint>
  <link name="right_eef_jaw_1">
    <inertial>
      <origin rpy="0 0 0" xyz="0.0869730343447335 -0.02 0.0799489474646907"/>
      <mass value="0.672155087926634"/>
      <inertia ixx="0.00170709281582639" ixy="-2.10297489845672E-19" ixz="-0.000828153130362926" iyy="0.00264620439405273" iyz="-1.13884847286996E-19" izz="0.00111534333500677"/>
    </inertial>
    <visual>
      <origin rpy="0 0 0" xyz="0 0 0"/>
      <geometry>
        <mesh filename="package://my_robot_urdf/meshes/eef_jaw_1.STL"/>
      </geometry>
      <material name="">
        <color rgba="0.792156862745098 0.819607843137255 0.933333333333333 1"/>
      </material>
    </visual>
    <collision>
      <origin rpy="0 0 0" xyz="0 0 0"/>
      <geometry>
        <mesh filename="package://my_robot_urdf/meshes/eef_jaw_1.STL"/>
      </geometry>
    </collision>
  </link>
  <joint name="right_eef_jaw_1_joint_fixed" type="fixed">
    <origin rpy="3.14159265358979 0 0" xyz="-0.222284161474005 -0.0199999999999985 -0.0299999999999994"/>
    <parent link="right_eef_link"/>
    <child link="right_eef_jaw_1"/>
    <axis xyz="0 0 0"/>
  </joint>
  <link name="right_eef_jaw_2">
    <inertial>
      <origin rpy="0 0 0" xyz="0.0869730343447341 0.02 -0.0799489474646903"/>
      <mass value="0.672155087926635"/>
      <inertia ixx="0.00170709281582639" ixy="-5.6339619860202E-19" ixz="0.000828153130362932" iyy="0.00264620439405273" iyz="3.28558952421928E-19" izz="0.00111534333500678"/>
    </inertial>
    <visual>
      <origin rpy="0 0 0" xyz="0 0 0"/>
      <geometry>
        <mesh filename="package://my_robot_urdf/meshes/eef_jaw_2.STL"/>
      </geometry>
      <material name="">
        <color rgba="0.792156862745098 0.819607843137255 0.933333333333333 1"/>
      </material>
    </visual>
    <collision>
      <origin rpy="0 0 0" xyz="0 0 0"/>
      <geometry>
        <mesh filename="package://my_robot_urdf/meshes/eef_jaw_2.STL"/>
      </geometry>
    </collision>
  </link>
  <joint name="right_eef_jaw_2_joint_fixed" type="fixed">
    <origin rpy="0 0 3.14159265358979" xyz="0.222284161474005 0.0200000000000028 -0.0300000000000008"/>
    <parent link="right_eef_link"/>
    <child link="right_eef_jaw_2"/>
    <axis xyz="0 0 0"/>
  </joint>
  <link name="right_eef_jaw_3">
    <inertial>
      <origin rpy="0 0 0" xyz="0.0869730343447339 0.0199999999999998 -0.0799489474646904"/>
      <mass value="0.672155087926635"/>
      <inertia ixx="0.00170709281582639" ixy="1.22645739197657E-18" ixz="0.000828153130362931" iyy="0.00264620439405273" iyz="-2.65524845194663E-18" izz="0.00111534333500678"/>
    </inertial>
    <visual>
      <origin rpy="0 0 0" xyz="0 0 0"/>
      <geometry>
        <mesh filename="package://my_robot_urdf/meshes/eef_jaw_3.STL"/>
      </geometry>
      <material name="">
        <color rgba="0.792156862745098 0.819607843137255 0.933333333333333 1"/>
      </material>
    </visual>
    <collision>
      <origin rpy="0 0 0" xyz="0 0 0"/>
      <geometry>
        <mesh filename="package://my_robot_urdf/meshes/eef_jaw_3.STL"/>
      </geometry>
    </collision>
  </link>
  <joint name="right_eef_jaw_3_joint_fixed" type="fixed">
    <origin rpy="0 0 1.5707963267949" xyz="0.02 -0.222284161474003 -0.03"/>
    <parent link="right_eef_link"/>
    <child link="right_eef_jaw_3"/>
    <axis xyz="0 0 0"/>
  </joint>
  <link name="right_eef_jaw_4">
    <inertial>
      <origin rpy="0 0 0" xyz="0.0869730343447339 0.02 -0.0799489474646904"/>
      <mass value="0.672155087926635"/>
      <inertia ixx="0.00170709281582639" ixy="-7.21958594590805E-19" ixz="0.00082815313036293" iyy="0.00264620439405273" iyz="3.18822450133064E-18" izz="0.00111534333500678"/>
    </inertial>
    <visual>
      <origin rpy="0 0 0" xyz="0 0 0"/>
      <geometry>
        <mesh filename="package://my_robot_urdf/meshes/eef_jaw_4.STL"/>
      </geometry>
      <material name="">
        <color rgba="0.792156862745098 0.819607843137255 0.933333333333333 1"/>
      </material>
    </visual>
    <collision>
      <origin rpy="0 0 0" xyz="0 0 0"/>
      <geometry>
        <mesh filename="package://my_robot_urdf/meshes/eef_jaw_4.STL"/>
      </geometry>
    </collision>
  </link>
  <joint name="right_eef_jaw_4_joint_fixed" type="fixed">
    <origin rpy="0 0 -1.5707963267949" xyz="-0.0200000000000002 0.222284161474006 -0.0299999999999999"/>
    <parent link="right_eef_link"/>
    <child link="right_eef_jaw_4"/>
    <axis xyz="0 0 0"/>
  </joint>
</robot>
