<?xml version="1.0" ?>
<!-- =================================================================================== -->
<!-- |    This document was autogenerated by xacro from robot.xacro                    | -->
<!-- |    EDITING THIS FILE BY HAND IS NOT RECOMMENDED                                 | -->
<!-- =================================================================================== -->
<robot name="my_robot">
  <link name="main_workbench">
    <inertial>
      <origin rpy="0 0 0" xyz="0 0 0.05"/>
      <mass value="1000.0"/>
      <inertia ixx="100" ixy="0" ixz="0" iyy="100" iyz="0" izz="100"/>
    </inertial>
    <visual>
      <origin rpy="0 0 0" xyz="0 0 0.05"/>
      <geometry>
        <box size="2 5 0.1"/>
      </geometry>
      <material name="grey">
        <color rgba="0.5 0.5 0.5 1"/>
        <!-- Workbench color -->
      </material>
    </visual>
    <collision>
      <origin rpy="0 0 0" xyz="0 0 0.05"/>
      <geometry>
        <box size="2 5 0.1"/>
      </geometry>
    </collision>
  </link>
  <link name="main_workbench_2">
    <inertial>
      <origin rpy="0 0 0" xyz="0 0 0.3"/>
      <mass value="1000.0"/>
      <inertia ixx="100" ixy="0" ixz="0" iyy="100" iyz="0" izz="100"/>
    </inertial>
    <visual>
      <origin rpy="0 0 0" xyz="0 0 0.3"/>
      <geometry>
        <box size="2 5 0.6"/>
      </geometry>
      <material name="grey">
        <color rgba="0.5 0.5 0.5 1"/>
        <!-- Workbench color -->
      </material>
    </visual>
    <collision>
      <origin rpy="0 0 0" xyz="0 0 0.3"/>
      <geometry>
        <box size="2 5 0.6"/>
      </geometry>
    </collision>
  </link>
  <!-- Main body link (central base link) -->
  <link name="central_base_link">
    <origin rpy="0 0 0" xyz="0 0 1.5"/>
    <!-- Adjusted to be above the workbench -->
  </link>
  <!-- Connect each workbench to the central base link with a fixed joint -->
  <joint name="base_to_workbench_1_joint" type="fixed">
    <parent link="central_base_link"/>
    <child link="main_workbench"/>
    <origin rpy="0 0 0" xyz="0 0 0"/>
  </joint>
  <joint name="base_to_workbench_2_joint" type="fixed">
    <parent link="central_base_link"/>
    <child link="main_workbench_2"/>
    <origin rpy="0 0 0" xyz="2.5 0 0"/>
  </joint>
  <!-- Define the base link of the arm -->
  <link name="alex_base_link">
    <inertial>
      <origin rpy="0 0 0" xyz="0 0 0.1"/>
      <mass value="33.891578448587"/>
      <inertia ixx="0.562042604088221" ixy="-9.14376784490416E-12" ixz="0.00403961419511076" iyy="0.970694427805805" iyz="-7.30601560182848E-12" izz="1.29713482615658"/>
    </inertial>
    <visual>
      <origin rpy="0 0 0" xyz="0 0 0"/>
      <geometry>
        <mesh filename="package://my_robot_urdf/meshes/base_link.STL"/>
      </geometry>
      <material name="">
        <color rgba="0.152941176470588 0 0.117647058823529 1"/>
      </material>
    </visual>
    <collision>
      <origin rpy="0 0 0" xyz="0 0 0"/>
      <geometry>
        <mesh filename="package://my_robot_urdf/meshes/base_link.STL"/>
      </geometry>
    </collision>
  </link>
  <!-- Define the joint connecting this arm to the parent link -->
  <joint name="alex_base_joint" type="fixed">
    <origin rpy="0 0 0" xyz="0 0 0.1"/>
    <parent link="central_base_link"/>
    <child link="alex_base_link"/>
  </joint>
  <link name="alex_arm_link_1">
    <inertial>
      <origin rpy="0 0 0" xyz="0.0416589398280025 -3.68988089329334E-05 0.19712083516126"/>
      <mass value="26.7048266497369"/>
      <inertia ixx="0.495499615132855" ixy="-0.0102760504758245" ixz="-0.0600935399650257" iyy="0.766768677077223" iyz="-0.0115358881770517" izz="0.604967931690783"/>
    </inertial>
    <visual>
      <origin rpy="0 0 0" xyz="0 0 0"/>
      <geometry>
        <mesh filename="package://my_robot_urdf/meshes/arm_link_1.STL"/>
      </geometry>
      <material name="">
        <color rgba="1 0.309803921568627 0.309803921568627 1"/>
      </material>
    </visual>
    <collision>
      <origin rpy="0 0 0" xyz="0 0 0"/>
      <geometry>
        <mesh filename="package://my_robot_urdf/meshes/arm_link_1.STL"/>
      </geometry>
    </collision>
  </link>
  <joint name="alex_arm_joint_1" type="revolute">
    <origin rpy="0 0 0" xyz="0 0 0.234000000000013"/>
    <parent link="alex_base_link"/>
    <child link="alex_arm_link_1"/>
    <axis xyz="0 0 1"/>
    <limit effort="0" lower="-3.1416" upper="3.1416" velocity="0"/>
  </joint>
  <link name="alex_arm_link_2">
    <inertial>
      <origin rpy="0 0 0" xyz="-0.290203503422467 0.000258724363916829 0.0707589768311214"/>
      <mass value="14.3270690802686"/>
      <inertia ixx="0.0504590836189902" ixy="4.64678003354567E-05" ixz="0.0137202067906074" iyy="0.848873613210201" iyz="-0.000175299197197552" izz="0.874803778149419"/>
    </inertial>
    <visual>
      <origin rpy="0 0 0" xyz="0 0 0"/>
      <geometry>
        <mesh filename="package://my_robot_urdf/meshes/arm_link_2.STL"/>
      </geometry>
      <material name="">
        <color rgba="0.792156862745098 0.819607843137255 0.933333333333333 1"/>
      </material>
    </visual>
    <collision>
      <origin rpy="0 0 0" xyz="0 0 0"/>
      <geometry>
        <mesh filename="package://my_robot_urdf/meshes/arm_link_2.STL"/>
      </geometry>
    </collision>
  </link>
  <joint name="alex_arm_joint_2" type="revolute">
    <origin rpy="1.5707963267949 0 0" xyz="0.150000000000002 -0.1375 0.265"/>
    <parent link="alex_arm_link_1"/>
    <child link="alex_arm_link_2"/>
    <axis xyz="0 0 1"/>
    <limit effort="0" lower="-3.1416" upper="3.1416" velocity="0"/>
  </joint>
  <link name="alex_arm_link_3">
    <inertial>
      <origin rpy="0 0 0" xyz="0.0664637155357432 0.0362614171159604 0.123132908024542"/>
      <mass value="27.1450417424437"/>
      <inertia ixx="0.420912669748457" ixy="-0.0211648441841247" ixz="-0.00675660536457725" iyy="0.344868303293538" iyz="0.00338242702861573" izz="0.473964503565446"/>
    </inertial>
    <visual>
      <origin rpy="0 0 0" xyz="0 0 0"/>
      <geometry>
        <mesh filename="package://my_robot_urdf/meshes/arm_link_3.STL"/>
      </geometry>
      <material name="">
        <color rgba="0.792156862745098 0.819607843137255 0.933333333333333 1"/>
      </material>
    </visual>
    <collision>
      <origin rpy="0 0 0" xyz="0 0 0"/>
      <geometry>
        <mesh filename="package://my_robot_urdf/meshes/arm_link_3.STL"/>
      </geometry>
    </collision>
  </link>
  <joint name="alex_arm_joint_3" type="continuous">
    <origin rpy="3.14159265358979 0 3.14159265358979" xyz="-0.700000000000001 0 0"/>
    <parent link="alex_arm_link_2"/>
    <child link="alex_arm_link_3"/>
    <axis xyz="0 0 -1"/>
    <limit effort="0" lower="-3.1416" upper="3.1416" velocity="0"/>
  </joint>
  <link name="alex_arm_link_4">
    <inertial>
      <origin rpy="0 0 0" xyz="5.19381656460816E-07 4.95817308893837E-07 0.338893744219759"/>
      <mass value="7.96664349020365"/>
      <inertia ixx="0.223048843574734" ixy="-0.000166072999280483" ixz="4.33220175839122E-07" iyy="0.215976713293833" iyz="-3.48765154255128E-07" izz="0.0300827685994122"/>
    </inertial>
    <visual>
      <origin rpy="0 0 0" xyz="0 0 0"/>
      <geometry>
        <mesh filename="package://my_robot_urdf/meshes/arm_link_4.STL"/>
      </geometry>
      <material name="">
        <color rgba="0.792156862745098 0.819607843137255 0.933333333333333 1"/>
      </material>
    </visual>
    <collision>
      <origin rpy="0 0 0" xyz="0 0 0"/>
      <geometry>
        <mesh filename="package://my_robot_urdf/meshes/arm_link_4.STL"/>
      </geometry>
    </collision>
  </link>
  <joint name="alex_arm_joint_4" type="revolute">
    <origin rpy="1.5707963267949 0 3.14159265358979" xyz="0.115 0.289996513803296 0.11"/>
    <parent link="alex_arm_link_3"/>
    <child link="alex_arm_link_4"/>
    <axis xyz="0 0 1"/>
    <limit effort="0" lower="-3.1416" upper="3.1416" velocity="0"/>
  </joint>
  <link name="alex_arm_link_5">
    <inertial>
      <origin rpy="0 0 0" xyz="-0.00224018993807718 -7.93515697594671E-10 -4.63650767085211E-10"/>
      <mass value="0.961734748124672"/>
      <inertia ixx="0.00154678090917305" ixy="8.85889008790739E-10" ixz="1.41969821668856E-11" iyy="0.00143991315628678" iyz="9.91727417863987E-10" izz="0.00165625576362529"/>
    </inertial>
    <visual>
      <origin rpy="0 0 0" xyz="0 0 0"/>
      <geometry>
        <mesh filename="package://my_robot_urdf/meshes/arm_link_5.STL"/>
      </geometry>
      <material name="">
        <color rgba="0.792156862745098 0.819607843137255 0.933333333333333 1"/>
      </material>
    </visual>
    <collision>
      <origin rpy="0 0 0" xyz="0 0 0"/>
      <geometry>
        <mesh filename="package://my_robot_urdf/meshes/arm_link_5.STL"/>
      </geometry>
    </collision>
  </link>
  <joint name="alex_arm_joint_5" type="revolute">
    <origin rpy="1.5707963267949 0 0" xyz="0 0 0.510003486196704"/>
    <parent link="alex_arm_link_4"/>
    <child link="alex_arm_link_5"/>
    <axis xyz="0 0 1"/>
    <limit effort="0" lower="-4.7124" upper="1.5708" velocity="0"/>
  </joint>
  <link name="alex_arm_link_6">
    <inertial>
      <origin rpy="0 0 0" xyz="2.47238263195726E-08 2.0518347576548E-09 0.052725963344278"/>
      <mass value="0.288779624800079"/>
      <inertia ixx="0.000386925186804297" ixy="-2.51402341445703E-12" ixz="-3.11942429904297E-13" iyy="0.000386925215104185" iyz="-2.74312353784785E-14" izz="0.000212753902483572"/>
    </inertial>
    <visual>
      <origin rpy="0 0 0" xyz="0 0 0"/>
      <geometry>
        <mesh filename="package://my_robot_urdf/meshes/arm_link_6.STL"/>
      </geometry>
      <material name="">
        <color rgba="0.792156862745098 0.819607843137255 0.933333333333333 1"/>
      </material>
    </visual>
    <collision>
      <origin rpy="0 0 0" xyz="0 0 0"/>
      <geometry>
        <mesh filename="package://my_robot_urdf/meshes/arm_link_6.STL"/>
      </geometry>
    </collision>
  </link>
  <joint name="alex_arm_joint_6" type="revolute">
    <origin rpy="-1.5707963267949 0 -1.5707963267949" xyz="0.0450000000000004 0 0"/>
    <parent link="alex_arm_link_5"/>
    <child link="alex_arm_link_6"/>
    <axis xyz="0 0 1"/>
    <limit effort="0" lower="-3.1416" upper="3.1416" velocity="0"/>
  </joint>
  <link name="alex_eef_link">
    <inertial>
      <origin rpy="0 0 0" xyz="-9.30830701406649E-09 -4.47423127714064E-09 -0.0188761945416884"/>
      <mass value="5.46782575492837"/>
      <inertia ixx="0.0365076087226209" ixy="-1.69594623176887E-09" ixz="2.84396742647187E-09" iyy="0.0365076302641158" iyz="1.3669924295319E-09" izz="0.0627860547898383"/>
    </inertial>
    <visual>
      <origin rpy="0 0 0" xyz="0 0 0"/>
      <geometry>
        <mesh filename="package://my_robot_urdf/meshes/eef_link.STL"/>
      </geometry>
      <material name="">
        <color rgba="0.792156862745098 0.819607843137255 0.933333333333333 1"/>
      </material>
    </visual>
    <collision>
      <origin rpy="0 0 0" xyz="0 0 0"/>
      <geometry>
        <mesh filename="package://my_robot_urdf/meshes/eef_link.STL"/>
      </geometry>
    </collision>
  </link>
  <joint name="alex_eef_link_fixed" type="fixed">
    <origin rpy="3.14159265358979 0 3.14159265358979" xyz="0 0 0.145"/>
    <parent link="alex_arm_link_6"/>
    <child link="alex_eef_link"/>
    <axis xyz="0 0 0"/>
  </joint>
  <link name="alex_eef_jaw_1">
    <inertial>
      <origin rpy="0 0 0" xyz="0.0869730343447335 -0.02 0.0799489474646907"/>
      <mass value="0.672155087926634"/>
      <inertia ixx="0.00170709281582639" ixy="-2.10297489845672E-19" ixz="-0.000828153130362926" iyy="0.00264620439405273" iyz="-1.13884847286996E-19" izz="0.00111534333500677"/>
    </inertial>
    <visual>
      <origin rpy="0 0 0" xyz="0 0 0"/>
      <geometry>
        <mesh filename="package://my_robot_urdf/meshes/eef_jaw_1.STL"/>
      </geometry>
      <material name="">
        <color rgba="0.792156862745098 0.819607843137255 0.933333333333333 1"/>
      </material>
    </visual>
    <collision>
      <origin rpy="0 0 0" xyz="0 0 0"/>
      <geometry>
        <mesh filename="package://my_robot_urdf/meshes/eef_jaw_1.STL"/>
      </geometry>
    </collision>
  </link>
  <joint name="alex_eef_jaw_1_joint_fixed" type="fixed">
    <origin rpy="3.14159265358979 0 0" xyz="-0.222284161474005 -0.0199999999999985 -0.0299999999999994"/>
    <parent link="alex_eef_link"/>
    <child link="alex_eef_jaw_1"/>
    <axis xyz="0 0 0"/>
  </joint>
  <link name="alex_eef_jaw_2">
    <inertial>
      <origin rpy="0 0 0" xyz="0.0869730343447341 0.02 -0.0799489474646903"/>
      <mass value="0.672155087926635"/>
      <inertia ixx="0.00170709281582639" ixy="-5.6339619860202E-19" ixz="0.000828153130362932" iyy="0.00264620439405273" iyz="3.28558952421928E-19" izz="0.00111534333500678"/>
    </inertial>
    <visual>
      <origin rpy="0 0 0" xyz="0 0 0"/>
      <geometry>
        <mesh filename="package://my_robot_urdf/meshes/eef_jaw_2.STL"/>
      </geometry>
      <material name="">
        <color rgba="0.792156862745098 0.819607843137255 0.933333333333333 1"/>
      </material>
    </visual>
    <collision>
      <origin rpy="0 0 0" xyz="0 0 0"/>
      <geometry>
        <mesh filename="package://my_robot_urdf/meshes/eef_jaw_2.STL"/>
      </geometry>
    </collision>
  </link>
  <joint name="alex_eef_jaw_2_joint_fixed" type="fixed">
    <origin rpy="0 0 3.14159265358979" xyz="0.222284161474005 0.0200000000000028 -0.0300000000000008"/>
    <parent link="alex_eef_link"/>
    <child link="alex_eef_jaw_2"/>
    <axis xyz="0 0 0"/>
  </joint>
  <link name="alex_eef_jaw_3">
    <inertial>
      <origin rpy="0 0 0" xyz="0.0869730343447339 0.0199999999999998 -0.0799489474646904"/>
      <mass value="0.672155087926635"/>
      <inertia ixx="0.00170709281582639" ixy="1.22645739197657E-18" ixz="0.000828153130362931" iyy="0.00264620439405273" iyz="-2.65524845194663E-18" izz="0.00111534333500678"/>
    </inertial>
    <visual>
      <origin rpy="0 0 0" xyz="0 0 0"/>
      <geometry>
        <mesh filename="package://my_robot_urdf/meshes/eef_jaw_3.STL"/>
      </geometry>
      <material name="">
        <color rgba="0.792156862745098 0.819607843137255 0.933333333333333 1"/>
      </material>
    </visual>
    <collision>
      <origin rpy="0 0 0" xyz="0 0 0"/>
      <geometry>
        <mesh filename="package://my_robot_urdf/meshes/eef_jaw_3.STL"/>
      </geometry>
    </collision>
  </link>
  <joint name="alex_eef_jaw_3_joint_fixed" type="fixed">
    <origin rpy="0 0 1.5707963267949" xyz="0.02 -0.222284161474003 -0.03"/>
    <parent link="alex_eef_link"/>
    <child link="alex_eef_jaw_3"/>
    <axis xyz="0 0 0"/>
  </joint>
  <link name="alex_eef_jaw_4">
    <inertial>
      <origin rpy="0 0 0" xyz="0.0869730343447339 0.02 -0.0799489474646904"/>
      <mass value="0.672155087926635"/>
      <inertia ixx="0.00170709281582639" ixy="-7.21958594590805E-19" ixz="0.00082815313036293" iyy="0.00264620439405273" iyz="3.18822450133064E-18" izz="0.00111534333500678"/>
    </inertial>
    <visual>
      <origin rpy="0 0 0" xyz="0 0 0"/>
      <geometry>
        <mesh filename="package://my_robot_urdf/meshes/eef_jaw_4.STL"/>
      </geometry>
      <material name="">
        <color rgba="0.792156862745098 0.819607843137255 0.933333333333333 1"/>
      </material>
    </visual>
    <collision>
      <origin rpy="0 0 0" xyz="0 0 0"/>
      <geometry>
        <mesh filename="package://my_robot_urdf/meshes/eef_jaw_4.STL"/>
      </geometry>
    </collision>
  </link>
  <joint name="alex_eef_jaw_4_joint_fixed" type="fixed">
    <origin rpy="0 0 -1.5707963267949" xyz="-0.0200000000000002 0.222284161474006 -0.0299999999999999"/>
    <parent link="alex_eef_link"/>
    <child link="alex_eef_jaw_4"/>
    <axis xyz="0 0 0"/>
  </joint>
  <link name="coco_base_link_coco">
    <inertial>
      <origin rpy="0 0 0" xyz="-0.0764021530191945 2.7134934886552E-05 0.0792317455056668"/>
      <mass value="33.7641312353281"/>
      <inertia ixx="0.388653917501998" ixy="4.13251669969691E-18" ixz="6.82570301647603E-05" iyy="0.347678993710906" iyz="9.1636908185897E-18" izz="0.646698533818771"/>
    </inertial>
    <visual>
      <origin rpy="0 0 0" xyz="0 0 0"/>
      <geometry>
        <mesh filename="package://my_robot_urdf/meshes/base_link_coco.STL"/>
      </geometry>
      <material name="">
        <color rgba="0.792156862745098 0.819607843137255 0.933333333333333 1"/>
      </material>
    </visual>
    <collision>
      <origin rpy="0 0 0" xyz="0 0 0"/>
      <geometry>
        <mesh filename="package://my_robot_urdf/meshes/base_link_coco.STL"/>
      </geometry>
    </collision>
  </link>
  <!-- Define the joint connecting this arm to the parent link -->
  <joint name="coco_base_joint_coco" type="fixed">
    <origin rpy="0 0 0" xyz="0 1 0.1"/>
    <parent link="central_base_link"/>
    <child link="coco_base_link_coco"/>
  </joint>
  <link name="coco_arm_link_1_coco">
    <inertial>
      <origin rpy="0 0 0" xyz="-0.0310954578647586 0.00332496023117711 0.134341853376388"/>
      <mass value="28.7973325809481"/>
      <inertia ixx="0.316024916828851" ixy="-0.000189061034524889" ixz="0.0129236801369765" iyy="0.322997369549128" iyz="0.000316914959622083" izz="0.500692862333896"/>
    </inertial>
    <visual>
      <origin rpy="0 0 0" xyz="0 0 0"/>
      <geometry>
        <mesh filename="package://my_robot_urdf/meshes/arm_link_1_coco.STL"/>
      </geometry>
      <material name="">
        <color rgba="0.792156862745098 0.819607843137255 0.933333333333333 1"/>
      </material>
    </visual>
    <collision>
      <origin rpy="0 0 0" xyz="0 0 0"/>
      <geometry>
        <mesh filename="package://my_robot_urdf/meshes/arm_link_1_coco.STL"/>
      </geometry>
    </collision>
  </link>
  <joint name="coco_joint_link_1_coco" type="revolute">
    <origin rpy="0 0 0" xyz="0 0 0.18"/>
    <parent link="coco_base_link_coco"/>
    <child link="coco_arm_link_1_coco"/>
    <axis xyz="0 0 1"/>
    <limit effort="0" lower="-3.1416" upper="3.1416" velocity="0"/>
  </joint>
  <link name="coco_arm_link_2_coco">
    <inertial>
      <origin rpy="0 0 0" xyz="-0.000939286588189411 0.316348210123725 0.119016776091287"/>
      <mass value="29.9902849835083"/>
      <inertia ixx="2.04087599375797" ixy="2.71567837661912E-12" ixz="6.90866563725407E-18" iyy="0.14290036636914" iyz="7.40531967035574E-16" izz="2.11684381896841"/>
    </inertial>
    <visual>
      <origin rpy="0 0 0" xyz="0 0 0"/>
      <geometry>
        <mesh filename="package://my_robot_urdf/meshes/arm_link_2_coco.STL"/>
      </geometry>
      <material name="">
        <color rgba="0.792156862745098 0.819607843137255 0.933333333333333 1"/>
      </material>
    </visual>
    <collision>
      <origin rpy="0 0 0" xyz="0 0 0"/>
      <geometry>
        <mesh filename="package://my_robot_urdf/meshes/arm_link_2_coco.STL"/>
      </geometry>
    </collision>
  </link>
  <joint name="coco_joint_link_2_coco" type="revolute">
    <origin rpy="1.5708 0.12064 -3.1416" xyz="-0.14579 0.090292 0.33595"/>
    <parent link="coco_arm_link_1_coco"/>
    <child link="coco_arm_link_2_coco"/>
    <axis xyz="0 0 1"/>
    <limit effort="0" lower="-3.1416" upper="3.1416" velocity="0"/>
  </joint>
  <link name="coco_arm_link_3_coco">
    <inertial>
      <origin rpy="0 0 0" xyz="0.112633238505252 -0.0799322649464853 0.0667859681669811"/>
      <mass value="16.9402164034933"/>
      <inertia ixx="0.147883770330323" ixy="0.094818491141768" ixz="0.0176568765175328" iyy="0.195654931378514" iyz="-0.0116926814719466" izz="0.274178448217779"/>
    </inertial>
    <visual>
      <origin rpy="0 0 0" xyz="0 0 0"/>
      <geometry>
        <mesh filename="package://my_robot_urdf/meshes/arm_link_3_coco.STL"/>
      </geometry>
      <material name="">
        <color rgba="0.792156862745098 0.819607843137255 0.933333333333333 1"/>
      </material>
    </visual>
    <collision>
      <origin rpy="0 0 0" xyz="0 0 0"/>
      <geometry>
        <mesh filename="package://my_robot_urdf/meshes/arm_link_3_coco.STL"/>
      </geometry>
    </collision>
  </link>
  <joint name="coco_joint_link_3_coco" type="revolute">
    <origin rpy="3.1416 0 2.5562" xyz="0.0017779 0.76236 0"/>
    <parent link="coco_arm_link_2_coco"/>
    <child link="coco_arm_link_3_coco"/>
    <axis xyz="0 0 -1"/>
    <limit effort="0" lower="-3.1416" upper="3.1416" velocity="0"/>
  </joint>
  <link name="coco_arm_link_4_coco">
    <inertial>
      <origin rpy="0 0 0" xyz="0.00566743707878439 0.0432831775720403 0.283218920418927"/>
      <mass value="7.44374239326319"/>
      <inertia ixx="0.159458719225964" ixy="-2.32546035320198E-05" ixz="0.000318756137369379" iyy="0.170907372375113" iyz="0.00563574921699865" izz="0.0394445449966552"/>
    </inertial>
    <visual>
      <origin rpy="0 0 0" xyz="0 0 0"/>
      <geometry>
        <mesh filename="package://my_robot_urdf/meshes/arm_link_4_coco.STL"/>
      </geometry>
      <material name="">
        <color rgba="0.792156862745098 0.819607843137255 0.933333333333333 1"/>
      </material>
    </visual>
    <collision>
      <origin rpy="0 0 0" xyz="0 0 0"/>
      <geometry>
        <mesh filename="package://my_robot_urdf/meshes/arm_link_4_coco.STL"/>
      </geometry>
    </collision>
  </link>
  <joint name="coco_joint_link_4_coco" type="revolute">
    <origin rpy="0 1.5708 0" xyz="0.25011 -0.19918 0.073652"/>
    <parent link="coco_arm_link_3_coco"/>
    <child link="coco_arm_link_4_coco"/>
    <axis xyz="0 0 1"/>
    <limit effort="0" lower="-3.1416" upper="3.1416" velocity="0"/>
  </joint>
  <link name="coco_arm_link_5_coco">
    <inertial>
      <origin rpy="0 0 0" xyz="0.0327073579947649 0.000399930122569447 -0.00635056152962845"/>
      <mass value="1.52714461517355"/>
      <inertia ixx="0.00405781083568541" ixy="-2.52022895116163E-06" ixz="-3.23424295631454E-07" iyy="0.00340193548011777" iyz="-3.63483013490502E-18" izz="0.00209047100682797"/>
    </inertial>
    <visual>
      <origin rpy="0 0 0" xyz="0 0 0"/>
      <geometry>
        <mesh filename="package://my_robot_urdf/meshes/arm_link_5_coco.STL"/>
      </geometry>
      <material name="">
        <color rgba="0.792156862745098 0.819607843137255 0.933333333333333 1"/>
      </material>
    </visual>
    <collision>
      <origin rpy="0 0 0" xyz="0 0 0"/>
      <geometry>
        <mesh filename="package://my_robot_urdf/meshes/arm_link_5_coco.STL"/>
      </geometry>
    </collision>
  </link>
  <joint name="coco_joint_link_5_coco" type="revolute">
    <origin rpy="1.5708 -0.32663 -1.5708" xyz="0 0.0061313 0.60723"/>
    <parent link="coco_arm_link_4_coco"/>
    <child link="coco_arm_link_5_coco"/>
    <axis xyz="0 0 1"/>
    <limit effort="0" lower="-3.1416" upper="3.1416" velocity="0"/>
  </joint>
  <link name="coco_arm_link_6_coco">
    <inertial>
      <origin rpy="0 0 0" xyz="6.83827994230057E-15 4.91162666094169E-13 0.00209660536067713"/>
      <mass value="0.0783717856165202"/>
      <inertia ixx="3.89729060157441E-05" ixy="-4.73467751418064E-22" ixz="3.90642805809135E-22" iyy="3.89729060157441E-05" iyz="-1.35525271560672E-20" izz="7.68229526638506E-05"/>
    </inertial>
    <visual>
      <origin rpy="0 0 0" xyz="0 0 0"/>
      <geometry>
        <mesh filename="package://my_robot_urdf/meshes/arm_link_6_coco.STL"/>
      </geometry>
      <material name="">
        <color rgba="0.792156862745098 0.819607843137255 0.933333333333333 1"/>
      </material>
    </visual>
    <collision>
      <origin rpy="0 0 0" xyz="0 0 0"/>
      <geometry>
        <mesh filename="package://my_robot_urdf/meshes/arm_link_6_coco.STL"/>
      </geometry>
    </collision>
  </link>
  <joint name="coco_arm_joint_6_coco" type="revolute">
    <origin rpy="0 1.5708 0" xyz="0.088678 -0.00048689 -0.0063488"/>
    <parent link="coco_arm_link_5_coco"/>
    <child link="coco_arm_link_6_coco"/>
    <axis xyz="0 0 1"/>
    <limit effort="0" lower="-3.1416" upper="3.1416" velocity="0"/>
  </joint>
  <link name="coco_eef_link_coco">
    <inertial>
      <origin rpy="0 0 0" xyz="-0.000160574398918121 1.1733226914501E-05 -0.0505537897313374"/>
      <mass value="0.0881458860458235"/>
      <inertia ixx="3.41606469042043E-05" ixy="-2.18364282658575E-08" ixz="-1.30675573106947E-07" iyy="3.38633990498516E-05" iyz="9.54819239022332E-09" izz="3.14208395202068E-05"/>
    </inertial>
    <visual>
      <origin rpy="0 0 0" xyz="0 0 0"/>
      <geometry>
        <mesh filename="package://my_robot_urdf/meshes/eef_link_coco.STL"/>
      </geometry>
      <material name="">
        <color rgba="0.792156862745098 0.819607843137255 0.933333333333333 1"/>
      </material>
    </visual>
    <collision>
      <origin rpy="0 0 0" xyz="0 0 0"/>
      <geometry>
        <mesh filename="package://my_robot_urdf/meshes/eef_link_coco.STL"/>
      </geometry>
    </collision>
  </link>
  <joint name="coco_eef_joint_fixed_coco" type="fixed">
    <origin rpy="0 0 0" xyz="0 0 0.079322"/>
    <parent link="coco_arm_link_6_coco"/>
    <child link="coco_eef_link_coco"/>
    <axis xyz="0 0 1"/>
  </joint>
  <link name="yuzi_base_link_yuzi">
    <inertial>
      <origin rpy="0 0 0" xyz="-5.47178888354305E-18 -9.68619783147112E-18 0.131559716820544"/>
      <mass value="13.926198063469"/>
      <inertia ixx="0.150359375184122" ixy="6.0086399695852E-18" ixz="-1.94495278139115E-17" iyy="0.150359375184122" iyz="-1.46529787170619E-17" izz="0.11575755967506"/>
    </inertial>
    <visual>
      <origin rpy="0 0 0" xyz="0 0 0"/>
      <geometry>
        <mesh filename="package://my_robot_urdf/meshes/base_link_yuzi.STL"/>
      </geometry>
      <material name="">
        <color rgba="0.792156862745098 0.819607843137255 0.933333333333333 1"/>
      </material>
    </visual>
    <collision>
      <origin rpy="0 0 0" xyz="0 0 0"/>
      <geometry>
        <mesh filename="package://my_robot_urdf/meshes/base_link_yuzi.STL"/>
      </geometry>
    </collision>
  </link>
  <joint name="yuzi_base_joint_yuzi" type="fixed">
    <origin rpy="0 0 0" xyz="0 2 0.1"/>
    <parent link="central_base_link"/>
    <child link="yuzi_base_link_yuzi"/>
  </joint>
  <link name="yuzi_arm_link_1_yuzi">
    <inertial>
      <origin rpy="0 0 0" xyz="0.0393277653963038 1.00151935087997E-07 0.150866622191122"/>
      <mass value="17.6840361237851"/>
      <inertia ixx="0.387077403080444" ixy="3.67268000730389E-07" ixz="-0.0824473388415476" iyy="0.281535059283111" iyz="6.7734118561898E-08" izz="0.349932526197817"/>
    </inertial>
    <visual>
      <origin rpy="0 0 0" xyz="0 0 0"/>
      <geometry>
        <mesh filename="package://my_robot_urdf/meshes/arm_link_1_yuzi.STL"/>
      </geometry>
      <material name="">
        <color rgba="0.780392156862745 0.8 0.788235294117647 1"/>
      </material>
    </visual>
    <collision>
      <origin rpy="0 0 0" xyz="0 0 0"/>
      <geometry>
        <mesh filename="package://my_robot_urdf/meshes/arm_link_1_yuzi.STL"/>
      </geometry>
    </collision>
  </link>
  <joint name="yuzi_joint_link_1_yuzi" type="revolute">
    <origin rpy="0 0 0" xyz="0 0 0.274"/>
    <parent link="yuzi_base_link_yuzi"/>
    <child link="yuzi_arm_link_1_yuzi"/>
    <axis xyz="0 0 1"/>
    <limit effort="0" lower="-3.1416" upper="3.1416" velocity="0"/>
  </joint>
  <link name="yuzi_arm_link_2_yuzi">
    <inertial>
      <origin rpy="0 0 0" xyz="5.93185936814677E-07 -0.202994951659398 -0.00270543986390563"/>
      <mass value="21.695061095067"/>
      <inertia ixx="0.29491156513822" ixy="2.31415083686566E-06" ixz="1.23997830999223E-09" iyy="0.0783160010403901" iyz="0.00039474385023762" izz="0.301877815458434"/>
    </inertial>
    <visual>
      <origin rpy="0 0 0" xyz="0 0 0"/>
      <geometry>
        <mesh filename="package://my_robot_urdf/meshes/arm_link_2_yuzi.STL"/>
      </geometry>
      <material name="">
        <color rgba="0.780392156862745 0.8 0.788235294117647 1"/>
      </material>
    </visual>
    <collision>
      <origin rpy="0 0 0" xyz="0 0 0"/>
      <geometry>
        <mesh filename="package://my_robot_urdf/meshes/arm_link_2_yuzi.STL"/>
      </geometry>
    </collision>
  </link>
  <joint name="yuzi_joint_link_2_yuzi" type="revolute">
    <origin rpy="-1.5707963267949 0 3.14159265358979" xyz="0.15 0 0.29"/>
    <parent link="yuzi_arm_link_1_yuzi"/>
    <child link="yuzi_arm_link_2_yuzi"/>
    <axis xyz="0 0 -1"/>
    <limit effort="0" lower="-1.5708" upper="1.5708" velocity="0"/>
  </joint>
  <link name="yuzi_arm_link_3_yuzi">
    <inertial>
      <origin rpy="0 0 0" xyz="0.000448863422053053 -0.0261515151771508 -0.00178825757799958"/>
      <mass value="4.48725682214161"/>
      <inertia ixx="0.00921991972060867" ixy="4.02687063686657E-19" ixz="-3.63081450440013E-35" iyy="0.0233991913614871" iyz="1.1070919909007E-35" izz="0.0219081787552183"/>
    </inertial>
    <visual>
      <origin rpy="0 0 0" xyz="0 0 0"/>
      <geometry>
        <mesh filename="package://my_robot_urdf/meshes/arm_link_3_yuzi.STL"/>
      </geometry>
      <material name="">
        <color rgba="0.792156862745098 0.819607843137255 0.933333333333333 1"/>
      </material>
    </visual>
    <collision>
      <origin rpy="0 0 0" xyz="0 0 0"/>
      <geometry>
        <mesh filename="package://my_robot_urdf/meshes/arm_link_3_yuzi.STL"/>
      </geometry>
    </collision>
  </link>
  <joint name="yuzi_joint_link_3_yuzi" type="revolute">
    <origin rpy="0 0 0" xyz="0 -0.575 0"/>
    <parent link="yuzi_arm_link_2_yuzi"/>
    <child link="yuzi_arm_link_3_yuzi"/>
    <axis xyz="0 0 -1"/>
    <limit effort="0" lower="-1.5708" upper="1.5708" velocity="0"/>
  </joint>
  <link name="yuzi_arm_link_4_yuzi">
    <inertial>
      <origin rpy="0 0 0" xyz="0 0.000932919736386198 0.288902507196118"/>
      <mass value="7.8906783291211"/>
      <inertia ixx="0.0897241931118628" ixy="-8.8004245382662E-20" ixz="-8.59860135949642E-19" iyy="0.0881400417573612" iyz="-0.000989909842324875" izz="0.0169814358788831"/>
    </inertial>
    <visual>
      <origin rpy="0 0 0" xyz="0 0 0"/>
      <geometry>
        <mesh filename="package://my_robot_urdf/meshes/arm_link_4_yuzi.STL"/>
      </geometry>
      <material name="">
        <color rgba="0.792156862745098 0.819607843137255 0.933333333333333 1"/>
      </material>
    </visual>
    <collision>
      <origin rpy="0 0 0" xyz="0 0 0"/>
      <geometry>
        <mesh filename="package://my_robot_urdf/meshes/arm_link_4_yuzi.STL"/>
      </geometry>
    </collision>
  </link>
  <joint name="yuzi_joint_link_4_yuzi" type="revolute">
    <origin rpy="1.5707963267949 0 -1.5707963267949" xyz="-0.1295 -0.0399999999999996 -0.00299999999999893"/>
    <parent link="yuzi_arm_link_3_yuzi"/>
    <child link="yuzi_arm_link_4_yuzi"/>
    <axis xyz="0 0 1"/>
    <limit effort="0" lower="-3.1416" upper="3.1416" velocity="0"/>
  </joint>
  <link name="yuzi_arm_link_5_yuzi">
    <inertial>
      <origin rpy="0 0 0" xyz="-0.0209881134676554 -1.11622497689368E-07 -0.00829305633881044"/>
      <mass value="0.684392926448249"/>
      <inertia ixx="0.000641087602858553" ixy="-1.13848125269319E-09" ixz="0.000110196226559993" iyy="0.00118845959430424" iyz="8.1268865171085E-12" izz="0.0013177404399051"/>
    </inertial>
    <visual>
      <origin rpy="0 0 0" xyz="0 0 0"/>
      <geometry>
        <mesh filename="package://my_robot_urdf/meshes/arm_link_5_yuzi.STL"/>
      </geometry>
      <material name="">
        <color rgba="0.792156862745098 0.819607843137255 0.933333333333333 1"/>
      </material>
    </visual>
    <collision>
      <origin rpy="0 0 0" xyz="0 0 0"/>
      <geometry>
        <mesh filename="package://my_robot_urdf/meshes/arm_link_5_yuzi.STL"/>
      </geometry>
    </collision>
  </link>
  <joint name="yuzi_joint_link_5_yuzi" type="revolute">
    <origin rpy="1.5707963267949 1.5707963267949 0" xyz="0 0 0.5455"/>
    <parent link="yuzi_arm_link_4_yuzi"/>
    <child link="yuzi_arm_link_5_yuzi"/>
    <axis xyz="0 0 -1"/>
    <limit effort="0" lower="-1.5708" upper="1.5708" velocity="0"/>
  </joint>
  <link name="yuzi_arm_link_6_yuzi">
    <inertial>
      <origin rpy="0 0 0" xyz="-4.44089209850063E-16 -1.92554305833426E-16 0.0329077161690579"/>
      <mass value="0.178247683979378"/>
      <inertia ixx="0.000122379302872283" ixy="4.06073363965986E-37" ixz="2.47306573660892E-20" iyy="0.000122379302872283" iyz="1.25710173290533E-21" izz="7.65887647797521E-05"/>
    </inertial>
    <visual>
      <origin rpy="0 0 0" xyz="0 0 0"/>
      <geometry>
        <mesh filename="package://my_robot_urdf/meshes/arm_link_6_yuzi.STL"/>
      </geometry>
      <material name="">
        <color rgba="0.792156862745098 0.819607843137255 0.933333333333333 1"/>
      </material>
    </visual>
    <collision>
      <origin rpy="0 0 0" xyz="0 0 0"/>
      <geometry>
        <mesh filename="package://my_robot_urdf/meshes/arm_link_6_yuzi.STL"/>
      </geometry>
    </collision>
  </link>
  <joint name="yuzi_joint_link_6_yuzi" type="revolute">
    <origin rpy="-1.5707963267949 0 1.5707963267949" xyz="-0.0850000000000001 0 0"/>
    <parent link="yuzi_arm_link_5_yuzi"/>
    <child link="yuzi_arm_link_6_yuzi"/>
    <axis xyz="0 0 1"/>
    <limit effort="0" lower="-3.1416" upper="3.1416" velocity="0"/>
  </joint>
</robot>
