<?xml version="1.0" encoding="utf-8"?>
<!-- This URDF was automatically created by SolidWorks to URDF Exporter! Originally created by Stephen Brawner (brawner@gmail.com) 
     Commit Version: 1.6.0-4-g7f85cfe  Build Version: 1.6.7995.38578
     For more information, please see http://wiki.ros.org/sw_urdf_exporter -->
<robot
  name="my_robot_urdf">
  <link
    name="${prefix}base_link_yuzi">
    <inertial>
      <origin
        xyz="-5.47178888354305E-18 -9.68619783147112E-18 0.131559716820544"
        rpy="0 0 0" />
      <mass
        value="13.926198063469" />
      <inertia
        ixx="0.150359375184122"
        ixy="6.0086399695852E-18"
        ixz="-1.94495278139115E-17"
        iyy="0.150359375184122"
        iyz="-1.46529787170619E-17"
        izz="0.11575755967506" />
    </inertial>
    <visual>
      <origin
        xyz="0 0 0"
        rpy="0 0 0" />
      <geometry>
        <mesh
          filename="package://my_robot_urdf/meshes/base_link_yuzi.STL" />
      </geometry>
      <material
        name="">
        <color
          rgba="0.792156862745098 0.819607843137255 0.933333333333333 1" />
      </material>
    </visual>
    <collision>
      <origin
        xyz="0 0 0"
        rpy="0 0 0" />
      <geometry>
        <mesh
          filename="package://my_robot_urdf/meshes/base_link_yuzi.STL" />
      </geometry>
    </collision>
  </link>
  <link
    name="${prefix}arm_link_1_yuzi">
    <inertial>
      <origin
        xyz="0.0393277653963038 1.00151935087997E-07 0.150866622191122"
        rpy="0 0 0" />
      <mass
        value="17.6840361237851" />
      <inertia
        ixx="0.387077403080444"
        ixy="3.67268000730389E-07"
        ixz="-0.0824473388415476"
        iyy="0.281535059283111"
        iyz="6.7734118561898E-08"
        izz="0.349932526197817" />
    </inertial>
    <visual>
      <origin
        xyz="0 0 0"
        rpy="0 0 0" />
      <geometry>
        <mesh
          filename="package://my_robot_urdf/meshes/arm_link_1_yuzi.STL" />
      </geometry>
      <material
        name="">
        <color
          rgba="0.780392156862745 0.8 0.788235294117647 1" />
      </material>
    </visual>
    <collision>
      <origin
        xyz="0 0 0"
        rpy="0 0 0" />
      <geometry>
        <mesh
          filename="package://my_robot_urdf/meshes/arm_link_1_yuzi.STL" />
      </geometry>
    </collision>
  </link>
  <joint
    name="${prefix}joint_link_1_yuzi"
    type="revolute">
    <origin
      xyz="0 0 0.274"
      rpy="0 0 0" />
    <parent
      link="${prefix}base_link_yuzi" />
    <child
      link="${prefix}arm_link_1_yuzi" />
    <axis
      xyz="0 0 1" />
    <limit
      lower="-3.1416"
      upper="3.1416"
      effort="0"
      velocity="0" />
  </joint>
  <link
    name="${prefix}arm_link_2_yuzi">
    <inertial>
      <origin
        xyz="5.93185936814677E-07 -0.202994951659398 -0.00270543986390563"
        rpy="0 0 0" />
      <mass
        value="21.695061095067" />
      <inertia
        ixx="0.29491156513822"
        ixy="2.31415083686566E-06"
        ixz="1.23997830999223E-09"
        iyy="0.0783160010403901"
        iyz="0.00039474385023762"
        izz="0.301877815458434" />
    </inertial>
    <visual>
      <origin
        xyz="0 0 0"
        rpy="0 0 0" />
      <geometry>
        <mesh
          filename="package://my_robot_urdf/meshes/arm_link_2_yuzi.STL" />
      </geometry>
      <material
        name="">
        <color
          rgba="0.780392156862745 0.8 0.788235294117647 1" />
      </material>
    </visual>
    <collision>
      <origin
        xyz="0 0 0"
        rpy="0 0 0" />
      <geometry>
        <mesh
          filename="package://my_robot_urdf/meshes/arm_link_2_yuzi.STL" />
      </geometry>
    </collision>
  </link>
  <joint
    name="${prefix}joint_link_2_yuzi"
    type="revolute">
    <origin
      xyz="0.15 0 0.29"
      rpy="-1.5707963267949 0 3.14159265358979" />
    <parent
      link="${prefix}arm_link_1_yuzi" />
    <child
      link="${prefix}arm_link_2_yuzi" />
    <axis
      xyz="0 0 -1" />
    <limit
      lower="-1.5708"
      upper="1.5708"
      effort="0"
      velocity="0" />
  </joint>
  <link
    name="${prefix}arm_link_3_yuzi">
    <inertial>
      <origin
        xyz="0.000448863422053053 -0.0261515151771508 -0.00178825757799958"
        rpy="0 0 0" />
      <mass
        value="4.48725682214161" />
      <inertia
        ixx="0.00921991972060867"
        ixy="4.02687063686657E-19"
        ixz="-3.63081450440013E-35"
        iyy="0.0233991913614871"
        iyz="1.1070919909007E-35"
        izz="0.0219081787552183" />
    </inertial>
    <visual>
      <origin
        xyz="0 0 0"
        rpy="0 0 0" />
      <geometry>
        <mesh
          filename="package://my_robot_urdf/meshes/arm_link_3_yuzi.STL" />
      </geometry>
      <material
        name="">
        <color
          rgba="0.792156862745098 0.819607843137255 0.933333333333333 1" />
      </material>
    </visual>
    <collision>
      <origin
        xyz="0 0 0"
        rpy="0 0 0" />
      <geometry>
        <mesh
          filename="package://my_robot_urdf/meshes/arm_link_3_yuzi.STL" />
      </geometry>
    </collision>
  </link>
  <joint
    name="${prefix}joint_link_3_yuzi"
    type="revolute">
    <origin
      xyz="0 -0.575 0"
      rpy="0 0 0" />
    <parent
      link="${prefix}arm_link_2_yuzi" />
    <child
      link="${prefix}arm_link_3_yuzi" />
    <axis
      xyz="0 0 -1" />
    <limit
      lower="-1.5708"
      upper="1.5708"
      effort="0"
      velocity="0" />
  </joint>
  <link
    name="${prefix}arm_link_4_yuzi">
    <inertial>
      <origin
        xyz="0 0.000932919736386198 0.288902507196118"
        rpy="0 0 0" />
      <mass
        value="7.8906783291211" />
      <inertia
        ixx="0.0897241931118628"
        ixy="-8.8004245382662E-20"
        ixz="-8.59860135949642E-19"
        iyy="0.0881400417573612"
        iyz="-0.000989909842324875"
        izz="0.0169814358788831" />
    </inertial>
    <visual>
      <origin
        xyz="0 0 0"
        rpy="0 0 0" />
      <geometry>
        <mesh
          filename="package://my_robot_urdf/meshes/arm_link_4_yuzi.STL" />
      </geometry>
      <material
        name="">
        <color
          rgba="0.792156862745098 0.819607843137255 0.933333333333333 1" />
      </material>
    </visual>
    <collision>
      <origin
        xyz="0 0 0"
        rpy="0 0 0" />
      <geometry>
        <mesh
          filename="package://my_robot_urdf/meshes/arm_link_4_yuzi.STL" />
      </geometry>
    </collision>
  </link>
  <joint
    name="${prefix}joint_link_4_yuzi"
    type="revolute">
    <origin
      xyz="-0.1295 -0.0399999999999996 -0.00299999999999893"
      rpy="1.5707963267949 0 -1.5707963267949" />
    <parent
      link="${prefix}arm_link_3_yuzi" />
    <child
      link="${prefix}arm_link_4_yuzi" />
    <axis
      xyz="0 0 1" />
    <limit
      lower="-3.1416"
      upper="3.1416"
      effort="0"
      velocity="0" />
  </joint>
  <link
    name="${prefix}arm_link_5_yuzi">
    <inertial>
      <origin
        xyz="-0.0209881134676554 -1.11622497689368E-07 -0.00829305633881044"
        rpy="0 0 0" />
      <mass
        value="0.684392926448249" />
      <inertia
        ixx="0.000641087602858553"
        ixy="-1.13848125269319E-09"
        ixz="0.000110196226559993"
        iyy="0.00118845959430424"
        iyz="8.1268865171085E-12"
        izz="0.0013177404399051" />
    </inertial>
    <visual>
      <origin
        xyz="0 0 0"
        rpy="0 0 0" />
      <geometry>
        <mesh
          filename="package://my_robot_urdf/meshes/arm_link_5_yuzi.STL" />
      </geometry>
      <material
        name="">
        <color
          rgba="0.792156862745098 0.819607843137255 0.933333333333333 1" />
      </material>
    </visual>
    <collision>
      <origin
        xyz="0 0 0"
        rpy="0 0 0" />
      <geometry>
        <mesh
          filename="package://my_robot_urdf/meshes/arm_link_5_yuzi.STL" />
      </geometry>
    </collision>
  </link>
  <joint
    name="${prefix}joint_link_5_yuzi"
    type="revolute">
    <origin
      xyz="0 0 0.5455"
      rpy="1.5707963267949 1.5707963267949 0" />
    <parent
      link="${prefix}arm_link_4_yuzi" />
    <child
      link="${prefix}arm_link_5_yuzi" />
    <axis
      xyz="0 0 -1" />
    <limit
      lower="-1.5708"
      upper="1.5708"
      effort="0"
      velocity="0" />
  </joint>
  <link
    name="${prefix}arm_link_6_yuzi">
    <inertial>
      <origin
        xyz="-4.44089209850063E-16 -1.92554305833426E-16 0.0329077161690579"
        rpy="0 0 0" />
      <mass
        value="0.178247683979378" />
      <inertia
        ixx="0.000122379302872283"
        ixy="4.06073363965986E-37"
        ixz="2.47306573660892E-20"
        iyy="0.000122379302872283"
        iyz="1.25710173290533E-21"
        izz="7.65887647797521E-05" />
    </inertial>
    <visual>
      <origin
        xyz="0 0 0"
        rpy="0 0 0" />
      <geometry>
        <mesh
          filename="package://my_robot_urdf/meshes/arm_link_6_yuzi.STL" />
      </geometry>
      <material
        name="">
        <color
          rgba="0.792156862745098 0.819607843137255 0.933333333333333 1" />
      </material>
    </visual>
    <collision>
      <origin
        xyz="0 0 0"
        rpy="0 0 0" />
      <geometry>
        <mesh
          filename="package://my_robot_urdf/meshes/arm_link_6_yuzi.STL" />
      </geometry>
    </collision>
  </link>
  <joint
    name="${prefix}joint_link_6_yuzi"
    type="revolute">
    <origin
      xyz="-0.0850000000000001 0 0"
      rpy="-1.5707963267949 0 1.5707963267949" />
    <parent
      link="${prefix}arm_link_5_yuzi" />
    <child
      link="${prefix}arm_link_6_yuzi" />
    <axis
      xyz="0 0 1" />
    <limit
      lower="-3.1416"
      upper="3.1416"
      effort="0"
      velocity="0" />
  </joint>
</robot>