<?xml version="1.0" ?>
<!-- =================================================================================== -->
<!-- |    This document was autogenerated by xacro from ../my_robot_urdf/urdf/robot.xacro | -->
<!-- |    EDITING THIS FILE BY HAND IS NOT RECOMMENDED                                 | -->
<!-- =================================================================================== -->
<robot name="my_robot">
    <link name="main_workbench">
        <inertial>
            <origin rpy="0 0 0" xyz="0 0 0.05" />
            <mass value="1000.0" />
            <inertia ixx="100" ixy="0" ixz="0" iyy="100" iyz="0" izz="100" />
        </inertial>
        <visual>
            <origin rpy="0 0 0" xyz="0 0 0.05" />
            <geometry>
                <box size="15 15 0.1" />
            </geometry>
            <material name="light_grey">
                <color rgba="0.7 0.7 0.7 1" />
                <!-- White grey color -->
            </material>
        </visual>
        <collision>
            <origin rpy="0 0 0" xyz="0 0 0.05" />
            <geometry>
                <box size="15 15 0.1" />
            </geometry>
        </collision>
    </link>
    <link name="main_workbench_2">
        <inertial>
            <origin rpy="0 0 0" xyz="0 0 0.375" />
            <mass value="1000.0" />
            <inertia ixx="100" ixy="0" ixz="0" iyy="100" iyz="0" izz="100" />
        </inertial>
        <visual>
            <origin rpy="0 0 0" xyz="0 0 0.375" />
            <geometry>
                <box size="0.8 5 0.75" />
            </geometry>
            <material name="rubber_black">
                <color rgba="0.05 0.05 0.05 1" />
                <!-- Dark grey to mimic black rubber -->
            </material>
        </visual>
        <collision>
            <origin rpy="0 0 0" xyz="0 0 0.375" />
            <geometry>
                <box size="0.8 5 0.75" />
            </geometry>
        </collision>
    </link>
    <link name="main_workbench_3">
        <inertial>
            <origin rpy="0 0 0" xyz="0 0 0.375" />
            <mass value="1000.0" />
            <inertia ixx="100" ixy="0" ixz="0" iyy="100" iyz="0" izz="100" />
        </inertial>
        <visual>
            <origin rpy="0 0 0" xyz="0 0 0.375" />
            <geometry>
                <box size="0.8 5 0.75" />
            </geometry>
            <material name="rubber_black">
                <color rgba="0.05 0.05 0.05 1" />
                <!-- Dark grey to mimic black rubber -->
            </material>
        </visual>
        <collision>
            <origin rpy="0 0 0" xyz="0 0 0.375" />
            <geometry>
                <box size="0.8 5 0.75" />
            </geometry>
        </collision>
    </link>
    <link name="centrifuge_1">
        <inertial>
            <origin rpy="0 0 0" xyz="0 0 0.375" />
            <mass value="500.0" />
            <!-- Assume a lighter mass for a centrifuge -->
            <inertia ixx="50" ixy="0" ixz="0" iyy="50" iyz="0" izz="50" />
            <!-- Adjusted inertia values for balance -->
        </inertial>
        <visual>
            <origin rpy="0 0 0" xyz="0 0 0.375" />
            <geometry>
                <cylinder length="0.75" radius="0.5" />
            </geometry>
            <material name="light_orange">
                <color rgba="1 0.65 0.2 1" />
                <!-- Light orange color -->
            </material>
        </visual>
        <collision>
            <origin rpy="0 0 0" xyz="0 0 0.375" />
            <geometry>
                <cylinder length="0.75" radius="0.5" />
            </geometry>
        </collision>
    </link>
    <link name="centrifuge_2">
        <inertial>
            <origin rpy="0 0 0" xyz="0 0 0.375" />
            <mass value="500.0" />
            <!-- Assume a lighter mass for a centrifuge -->
            <inertia ixx="50" ixy="0" ixz="0" iyy="50" iyz="0" izz="50" />
            <!-- Adjusted inertia values for balance -->
        </inertial>
        <visual>
            <origin rpy="0 0 0" xyz="0 0 0.375" />
            <geometry>
                <cylinder length="0.75" radius="0.5" />
            </geometry>
            <material name="light_orange">
                <color rgba="1 0.65 0.2 1" />
                <!-- Light orange color -->
            </material>
        </visual>
        <collision>
            <origin rpy="0 0 0" xyz="0 0 0.375" />
            <geometry>
                <cylinder length="0.75" radius="0.5" />
            </geometry>
        </collision>
    </link>
    <!-- Main body link (central base link) -->
    <link name="central_base_link">
        <origin rpy="0 0 0" xyz="0 0 1.5" />
        <!-- Adjusted to be above the workbench -->
    </link>
    <!-- Connect each workbench to the central base link with a fixed joint -->
    <joint name="base_to_workbench_1_joint" type="fixed">
        <parent link="central_base_link" />
        <child link="main_workbench" />
        <origin rpy="0 0 0" xyz="0 0 0" />
    </joint>
    <joint name="base_to_workbench_2_joint" type="fixed">
        <parent link="central_base_link" />
        <child link="main_workbench_2" />
        <origin rpy="0 0 0" xyz="2.2 -2.5 0" />
    </joint>
    <joint name="base_to_workbench_3_joint" type="fixed">
        <parent link="central_base_link" />
        <child link="main_workbench_3" />
        <origin rpy="0 0 0" xyz="-2.2 -2.5 0" />
    </joint>
    <!-- Connect each centrifuge to the central base link with a fixed joint -->
    <joint name="base_to_centrifuge_1_joint" type="fixed">
        <parent link="central_base_link" />
        <child link="centrifuge_1" />
        <origin rpy="0 0 0" xyz="1.7 1.2 0" />
    </joint>
    <joint name="base_to_centrifuge_2_joint" type="fixed">
        <parent link="central_base_link" />
        <child link="centrifuge_2" />
        <origin rpy="0 0 0" xyz="-1.7 1.2 0" />
    </joint>
    <link name="alex_base_link_alex">
        <inertial>
            <origin rpy="0 0 0" xyz="-0.05930869488714 -2.87595388123997E-12 0.0776653157730273" />
            <mass value="33.891578448587" />
            <inertia ixx="0.562042604088221" ixy="-9.14377057009813E-12" ixz="0.00403961419511078" iyy="0.970694427805805" iyz="-7.30601565928646E-12" izz="1.29713482615658" />
        </inertial>
        <visual>
            <origin rpy="0 0 0" xyz="0 0 0" />
            <geometry>
                <mesh filename="package://my_robot_urdf/meshes/base_link_alex.STL" />
            </geometry>
            <material name="">
                <color rgba="0.152941176470588 0 0.117647058823529 1" />
            </material>
        </visual>
        <collision>
            <origin rpy="0 0 0" xyz="0 0 0" />
            <geometry>
                <mesh filename="package://my_robot_urdf/meshes/base_link_alex.STL" />
            </geometry>
        </collision>
    </link>
    <!-- Define the joint connecting this arm to the parent link -->
    <joint name="alex_base_joint_alex" type="fixed">
        <origin rpy="0 0 3.14159265359" xyz="-1 0 0.1" />
        <parent link="central_base_link" />
        <child link="alex_base_link_alex" />
    </joint>
    <link name="alex_arm_link_1_alex">
        <inertial>
            <origin rpy="0 0 0" xyz="0.0416589398280025 -3.68988089329334E-05 0.19712083516126" />
            <mass value="26.7048266497369" />
            <inertia ixx="0.495499615132855" ixy="-0.0102760504758245" ixz="-0.0600935399650257" iyy="0.766768677077223" iyz="-0.0115358881770517" izz="0.604967931690783" />
        </inertial>
        <visual>
            <origin rpy="0 0 0" xyz="0 0 0" />
            <geometry>
                <mesh filename="package://my_robot_urdf/meshes/arm_link_1_alex.STL" />
            </geometry>
            <material name="">
                <color rgba="1 0 0 1" />
            </material>
        </visual>
        <collision>
            <origin rpy="0 0 0" xyz="0 0 0" />
            <geometry>
                <mesh filename="package://my_robot_urdf/meshes/arm_link_1_alex.STL" />
            </geometry>
        </collision>
    </link>
    <joint name="alex_arm_joint_1_alex" type="revolute">
        <origin rpy="0 0 0" xyz="0 0 0.234" />
        <parent link="alex_base_link_alex" />
        <child link="alex_arm_link_1_alex" />
        <axis xyz="0 0 1" />
        <limit effort="0" lower="-3.1416" upper="3.1416" velocity="0" />
    </joint>
    <link name="alex_arm_link_2_alex">
        <inertial>
            <origin rpy="0 0 0" xyz="0.000258724363916746 -0.0707589768311214 0.290203503422467" />
            <mass value="14.3270690802686" />
            <inertia ixx="0.848873613210201" ixy="0.000175299197197544" ixz="-4.64678003354308E-05" iyy="0.874803778149419" iyz="0.0137202067906074" izz="0.0504590836189902" />
        </inertial>
        <visual>
            <origin rpy="0 0 0" xyz="0 0 0" />
            <geometry>
                <mesh filename="package://my_robot_urdf/meshes/arm_link_2_alex.STL" />
            </geometry>
            <material name="">
                <color rgba="0.792156862745098 0.819607843137255 0.933333333333333 1" />
            </material>
        </visual>
        <collision>
            <origin rpy="0 0 0" xyz="0 0 0" />
            <geometry>
                <mesh filename="package://my_robot_urdf/meshes/arm_link_2_alex.STL" />
            </geometry>
        </collision>
    </link>
    <joint name="alex_arm_joint_2_alex" type="revolute">
        <origin rpy="0 0 0" xyz="0.15 -0.1375 0.265" />
        <parent link="alex_arm_link_1_alex" />
        <child link="alex_arm_link_2_alex" />
        <axis xyz="0 1 0" />
        <limit effort="0" lower="-3.1416" upper="3.1416" velocity="0" />
    </joint>
    <link name="alex_arm_link_3_alex">
        <inertial>
            <origin rpy="0 0 0" xyz="0.0362614171159604 0.143132908024542 0.0664637155357433" />
            <mass value="27.1450417424437" />
            <inertia ixx="0.344868303293537" ixy="0.00338242702861572" ixz="-0.0211648441841246" iyy="0.473964503565446" iyz="-0.00675660536457731" izz="0.420912669748457" />
        </inertial>
        <visual>
            <origin rpy="0 0 0" xyz="0 0 0" />
            <geometry>
                <mesh filename="package://my_robot_urdf/meshes/arm_link_3_alex.STL" />
            </geometry>
            <material name="">
                <color rgba="0.792156862745098 0.819607843137255 0.933333333333333 1" />
            </material>
        </visual>
        <collision>
            <origin rpy="0 0 0" xyz="0 0 0" />
            <geometry>
                <mesh filename="package://my_robot_urdf/meshes/arm_link_3_alex.STL" />
            </geometry>
        </collision>
    </link>
    <joint name="alex_arm_joint_3_alex" type="revolute">
        <origin rpy="0 0 0" xyz="0 0 0.7" />
        <parent link="alex_arm_link_2_alex" />
        <child link="alex_arm_link_3_alex" />
        <axis xyz="0 1 0" />
        <limit effort="0" lower="-3.1416" upper="3.1416" velocity="0" />
    </joint>
    <link name="alex_arm_link_4_alex">
        <inertial>
            <origin rpy="0 0 0" xyz="0.316053837217416 -9.61729624260159E-07 4.81067610857977E-07" />
            <mass value="9.30858027519608" />
            <inertia ixx="0.0348463133234508" ixy="7.6582656016075E-07" ixz="3.49084068434524E-07" iyy="0.25723918092213" iyz="0.000166705964846771" izz="0.264212206266023" />
        </inertial>
        <visual>
            <origin rpy="0 0 0" xyz="0 0 0" />
            <geometry>
                <mesh filename="package://my_robot_urdf/meshes/arm_link_4_alex.STL" />
            </geometry>
            <material name="">
                <color rgba="0.792156862745098 0.819607843137255 0.933333333333333 1" />
            </material>
        </visual>
        <collision>
            <origin rpy="0 0 0" xyz="0 0 0" />
            <geometry>
                <mesh filename="package://my_robot_urdf/meshes/arm_link_4_alex.STL" />
            </geometry>
        </collision>
    </link>
    <joint name="alex_arm_joint_4_alex" type="revolute">
        <origin rpy="0 0 0" xyz="0.29 0.13 0.115" />
        <parent link="alex_arm_link_3_alex" />
        <child link="alex_arm_link_4_alex" />
        <axis xyz="1 0 0" />
        <limit effort="0" lower="-3.1416" upper="3.1416" velocity="0" />
    </joint>
    <link name="alex_arm_link_5_alex">
        <inertial>
            <origin rpy="0 0 0" xyz="-0.00224018993807718 -4.63651143520205E-10 7.93515697594671E-10" />
            <mass value="0.961734748124672" />
            <inertia ixx="0.00154678090917305" ixy="1.419698244829E-11" ixz="-8.85889011205107E-10" iyy="0.00165625576362529" iyz="-9.91727417077089E-10" izz="0.00143991315628678" />
        </inertial>
        <visual>
            <origin rpy="0 0 0" xyz="0 0 0" />
            <geometry>
                <mesh filename="package://my_robot_urdf/meshes/arm_link_5_alex.STL" />
            </geometry>
            <material name="">
                <color rgba="0.792156862745098 0.819607843137255 0.933333333333333 1" />
            </material>
        </visual>
        <collision>
            <origin rpy="0 0 0" xyz="0 0 0" />
            <geometry>
                <mesh filename="package://my_robot_urdf/meshes/arm_link_5_alex.STL" />
            </geometry>
        </collision>
    </link>
    <joint name="alex_arm_joint_5_alex" type="revolute">
        <origin rpy="0 0 0" xyz="0.51 0 0" />
        <parent link="alex_arm_link_4_alex" />
        <child link="alex_arm_link_5_alex" />
        <axis xyz="0 1 0" />
        <limit effort="0" lower="-3.1416" upper="3.1416" velocity="0" />
    </joint>
    <link name="alex_arm_link_6_alex">
        <inertial>
            <origin rpy="0 0 0" xyz="2.47238264115129E-08 2.05183470214365E-09 0.0527259633442777" />
            <mass value="0.288779624800079" />
            <inertia ixx="0.000386925186804296" ixy="-2.51402341991393E-12" ixz="-3.11942264818914E-13" iyy="0.000386925215104184" iyz="-2.74312811357832E-14" izz="0.000212753902483571" />
        </inertial>
        <visual>
            <origin rpy="0 0 0" xyz="0 0 0" />
            <geometry>
                <mesh filename="package://my_robot_urdf/meshes/arm_link_6_alex.STL" />
            </geometry>
            <material name="">
                <color rgba="0.792156862745098 0.819607843137255 0.933333333333333 1" />
            </material>
        </visual>
        <collision>
            <origin rpy="0 0 0" xyz="0 0 0" />
            <geometry>
                <mesh filename="package://my_robot_urdf/meshes/arm_link_6_alex.STL" />
            </geometry>
        </collision>
    </link>
    <joint name="alex_arm_joint_6_alex" type="revolute">
        <origin rpy="1.5708 0 1.5708" xyz="0.045 0 0" />
        <parent link="alex_arm_link_5_alex" />
        <child link="alex_arm_link_6_alex" />
        <axis xyz="0 0 1" />
        <limit effort="0" lower="-1.5708" upper="4.7124" velocity="0" />
    </joint>
    <link name="alex_eef_link_alex">
        <inertial>
            <origin rpy="0 0 0" xyz="2.38264269425414E-13 -2.66453525910038E-15 -0.0980561329200587" />
            <mass value="1.45406661810263" />
            <inertia ixx="0.00681334885577991" ixy="4.74320102087839E-09" ixz="-7.63267180505381E-14" iyy="0.00863071846569575" iyz="4.48393921534639E-16" izz="0.00243700011056295" />
        </inertial>
        <visual>
            <origin rpy="0 0 0" xyz="0 0 0" />
            <geometry>
                <mesh filename="package://my_robot_urdf/meshes/eef_link_alex.STL" />
            </geometry>
            <material name="">
                <color rgba="0.792156862745098 0.819607843137255 0.933333333333333 1" />
            </material>
        </visual>
        <collision>
            <origin rpy="0 0 0" xyz="0 0 0" />
            <geometry>
                <mesh filename="package://my_robot_urdf/meshes/eef_link_alex.STL" />
            </geometry>
        </collision>
    </link>
    <joint name="alex_eef_joint_fixed_alex" type="fixed">
        <origin rpy="0 0 3.1416" xyz="0 0 0.32173" />
        <parent link="alex_arm_link_6_alex" />
        <child link="alex_eef_link_alex" />
        <axis xyz="0 0 0" />
    </joint>
    <link name="coco_base_link_coco">
        <inertial>
            <origin rpy="0 0 0" xyz="-0.0764021530191944 2.71349348865524E-05 0.0792317455056668" />
            <mass value="33.7641312353281" />
            <inertia ixx="0.388653917501998" ixy="3.75787448655195E-18" ixz="6.82570301647603E-05" iyy="0.347678993710906" iyz="8.89625811535709E-18" izz="0.646698533818771" />
        </inertial>
        <visual>
            <origin rpy="0 0 0" xyz="0 0 0" />
            <geometry>
                <mesh filename="package://my_robot_urdf/meshes/base_link_coco.STL" />
            </geometry>
            <material name="">
                <color rgba="0.792156862745098 0.819607843137255 0.933333333333333 1" />
            </material>
        </visual>
        <collision>
            <origin rpy="0 0 0" xyz="0 0 0" />
            <geometry>
                <mesh filename="package://my_robot_urdf/meshes/base_link_coco.STL" />
            </geometry>
        </collision>
    </link>
    <!-- Define the joint connecting this arm to the parent link -->
    <joint name="coco_base_joint_coco" type="fixed">
        <origin rpy="0 0 0" xyz="0 1 0.1" />
        <parent link="central_base_link" />
        <child link="coco_base_link_coco" />
    </joint>
    <link name="coco_arm_link_1_coco">
        <inertial>
            <origin rpy="0 0 0" xyz="0.0310954578647585 -0.00332496023117675 0.134341853376388" />
            <mass value="28.7973325809481" />
            <inertia ixx="0.316024916828851" ixy="-0.000189061034524887" ixz="-0.0129236801369765" iyy="0.322997369549128" iyz="-0.000316914959622081" izz="0.500692862333896" />
        </inertial>
        <visual>
            <origin rpy="0 0 0" xyz="0 0 0" />
            <geometry>
                <mesh filename="package://my_robot_urdf/meshes/arm_link_1_coco.STL" />
            </geometry>
            <material name="">
                <color rgba="0.792156862745098 0.819607843137255 0.933333333333333 1" />
            </material>
        </visual>
        <collision>
            <origin rpy="0 0 0" xyz="0 0 0" />
            <geometry>
                <mesh filename="package://my_robot_urdf/meshes/arm_link_1_coco.STL" />
            </geometry>
        </collision>
    </link>
    <joint name="coco_joint_link_1_coco" type="revolute">
        <origin rpy="0 0 0" xyz="0 0 0.18" />
        <parent link="coco_base_link_coco" />
        <child link="coco_arm_link_1_coco" />
        <axis xyz="0 0 1" />
        <limit effort="0" lower="-3.1416" upper="3.1416" velocity="0" />
    </joint>
    <link name="coco_arm_link_2_coco">
        <inertial>
            <origin rpy="0 0 0" xyz="-0.000939286587736787 0.316348210123726 0.119016776091287" />
            <mass value="29.9902849835083" />
            <inertia ixx="2.04087599375796" ixy="6.72038874095361E-18" ixz="2.43431801579158E-17" iyy="0.14290036636914" iyz="1.09136139887468E-17" izz="2.11684381896841" />
        </inertial>
        <visual>
            <origin rpy="0 0 0" xyz="0 0 0" />
            <geometry>
                <mesh filename="package://my_robot_urdf/meshes/arm_link_2_coco.STL" />
            </geometry>
            <material name="">
                <color rgba="0.792156862745098 0.819607843137255 0.933333333333333 1" />
            </material>
        </visual>
        <collision>
            <origin rpy="0 0 0" xyz="0 0 0" />
            <geometry>
                <mesh filename="package://my_robot_urdf/meshes/arm_link_2_coco.STL" />
            </geometry>
        </collision>
    </link>
    <joint name="coco_joint_link_2_coco" type="revolute">
        <origin rpy="1.5708 0 0" xyz="0.14579 -0.090292 0.33595" />
        <parent link="coco_arm_link_1_coco" />
        <child link="coco_arm_link_2_coco" />
        <axis xyz="0 0 1" />
        <limit effort="0" lower="-3.1416" upper="3.1416" velocity="0" />
    </joint>
    <link name="coco_arm_link_3_coco">
        <inertial>
            <origin rpy="0 0 0" xyz="-0.106966394959347 0.0865335610269826 0.0663605481820073" />
            <mass value="16.1199771168543" />
            <inertia ixx="0.137763861529296" ixy="0.0959483935903455" ixz="-0.0167225971301647" iyy="0.190812936291584" iyz="0.012987856550598" izz="0.261074961271267" />
        </inertial>
        <visual>
            <origin rpy="0 0 0" xyz="0 0 0" />
            <geometry>
                <mesh filename="package://my_robot_urdf/meshes/arm_link_3_coco.STL" />
            </geometry>
            <material name="">
                <color rgba="0.792156862745098 0.819607843137255 0.933333333333333 1" />
            </material>
        </visual>
        <collision>
            <origin rpy="0 0 0" xyz="0 0 0" />
            <geometry>
                <mesh filename="package://my_robot_urdf/meshes/arm_link_3_coco.STL" />
            </geometry>
        </collision>
    </link>
    <joint name="coco_joint_link_3_coco" type="revolute">
        <origin rpy="3.1416 0 3.1416" xyz="0.0017779 0.76236 0" />
        <parent link="coco_arm_link_2_coco" />
        <child link="coco_arm_link_3_coco" />
        <axis xyz="0 0 -1" />
        <limit effort="0" lower="-3.1416" upper="3.1416" velocity="0" />
    </joint>
    <link name="coco_arm_link_4_coco">
        <inertial>
            <origin rpy="0 0 0" xyz="0.00589018251913124 0.0329551371731716 0.164539778953426" />
            <mass value="8.2144132017799" />
            <inertia ixx="0.160372113366996" ixy="-1.53545094183617E-06" ixz="-1.62360283324988E-05" iyy="0.164102263665489" iyz="-0.0168710233275404" izz="0.0518416725365331" />
        </inertial>
        <visual>
            <origin rpy="0 0 0" xyz="0 0 0" />
            <geometry>
                <mesh filename="package://my_robot_urdf/meshes/arm_link_4_coco.STL" />
            </geometry>
            <material name="">
                <color rgba="0.792156862745098 0.819607843137255 0.933333333333333 1" />
            </material>
        </visual>
        <collision>
            <origin rpy="0 0 0" xyz="0 0 0" />
            <geometry>
                <mesh filename="package://my_robot_urdf/meshes/arm_link_4_coco.STL" />
            </geometry>
        </collision>
    </link>
    <joint name="coco_joint_link_4_coco" type="revolute">
        <origin rpy="3.1416 -1.5708 3.1416" xyz="-0.34817 0.19918 0.073652" />
        <parent link="coco_arm_link_3_coco" />
        <child link="coco_arm_link_4_coco" />
        <axis xyz="0 0 1" />
        <limit effort="0" lower="-3.1416" upper="3.1416" velocity="0" />
    </joint>
    <link name="coco_arm_link_5_coco">
        <inertial>
            <origin rpy="0 0 0" xyz="0.010949759264604 0.000150612983941256 -0.00279641564862637" />
            <mass value="1.15468077380916" />
            <inertia ixx="0.0024180307299129" ixy="-7.71125501828698E-06" ixz="6.55345310597226E-07" iyy="0.00301389716175276" iyz="9.01091984503082E-09" izz="0.00180806969473038" />
        </inertial>
        <visual>
            <origin rpy="0 0 0" xyz="0 0 0" />
            <geometry>
                <mesh filename="package://my_robot_urdf/meshes/arm_link_5_coco.STL" />
            </geometry>
            <material name="">
                <color rgba="0.792156862745098 0.819607843137255 0.933333333333333 1" />
            </material>
        </visual>
        <collision>
            <origin rpy="0 0 0" xyz="0 0 0" />
            <geometry>
                <mesh filename="package://my_robot_urdf/meshes/arm_link_5_coco.STL" />
            </geometry>
        </collision>
    </link>
    <joint name="coco_joint_link_5_coco" type="revolute">
        <origin rpy="3.1416 -1.5708 0" xyz="0 0.0656 0.50466" />
        <parent link="coco_arm_link_4_coco" />
        <child link="coco_arm_link_5_coco" />
        <axis xyz="0 0 1" />
        <limit effort="0" lower="-3.1416" upper="3.1416" velocity="0" />
    </joint>
    <link name="coco_arm_link_6_coco">
        <inertial>
            <origin rpy="0 0 0" xyz="-5.1833373264849E-05 0.000526764504232613 0.074050240735366" />
            <mass value="1.15468077380916" />
            <inertia ixx="0.00180806969473038" ixy="9.01091984507194E-09" ixz="6.55345310597047E-07" iyy="0.00301389716175276" iyz="-7.71125501828711E-06" izz="0.0024180307299129" />
        </inertial>
        <visual>
            <origin rpy="0 0 0" xyz="0 0 0" />
            <geometry>
                <mesh filename="package://my_robot_urdf/meshes/arm_link_6_coco.STL" />
            </geometry>
            <material name="">
                <color rgba="0.792156862745098 0.819607843137255 0.933333333333333 1" />
            </material>
        </visual>
        <collision>
            <origin rpy="0 0 0" xyz="0 0 0" />
            <geometry>
                <mesh filename="package://my_robot_urdf/meshes/arm_link_6_coco.STL" />
            </geometry>
        </collision>
    </link>
    <joint name="coco_arm_joint_6_coco" type="revolute">
        <origin rpy="0 1.5708 0" xyz="0.085 0.00067738 -0.0028482" />
        <parent link="coco_arm_link_5_coco" />
        <child link="coco_arm_link_6_coco" />
        <axis xyz="0 0 -1" />
        <limit effort="0" lower="-3.1416" upper="3.1416" velocity="0" />
    </joint>
    <link name="coco_eef_link_1_coco">
        <inertial>
            <origin rpy="0 0 0" xyz="3.29649640917751E-11 -9.235071400715E-05 -0.124708296392705" />
            <mass value="0.15332063940157" />
            <inertia ixx="8.3412429703298E-05" ixy="9.18634115356551E-14" ixz="-1.79341490009726E-13" iyy="8.37120102622999E-05" iyz="1.37052372054436E-07" izz="0.000136601285012748" />
        </inertial>
        <visual>
            <origin rpy="0 0 0" xyz="0 0 0" />
            <geometry>
                <mesh filename="package://my_robot_urdf/meshes/eef_link_1_coco.STL" />
            </geometry>
            <material name="">
                <color rgba="0.792156862745098 0.819607843137255 0.933333333333333 1" />
            </material>
        </visual>
        <collision>
            <origin rpy="0 0 0" xyz="0 0 0" />
            <geometry>
                <mesh filename="package://my_robot_urdf/meshes/eef_link_1_coco.STL" />
            </geometry>
        </collision>
    </link>
    <joint name="coco_eef_joint_1_fixed_coco" type="fixed">
        <origin rpy="-1.5708 0 -1.5708" xyz="0.20975 0.00067738 0.085" />
        <parent link="coco_arm_link_6_coco" />
        <child link="coco_eef_link_1_coco" />
        <axis xyz="0 0 0" />
    </joint>
    <link name="coco_eef_link_2_coco">
        <inertial>
            <origin rpy="0 0 0" xyz="0 0 -0.0480792617128722" />
            <mass value="0.158859300753402" />
            <inertia ixx="0.000149672253524412" ixy="-4.9614680881843E-21" ixz="7.79229232056955E-22" iyy="0.000192557897320206" iyz="1.28004734861553E-20" izz="0.00016094527647324" />
        </inertial>
        <visual>
            <origin rpy="0 0 0" xyz="0 0 0" />
            <geometry>
                <mesh filename="package://my_robot_urdf/meshes/eef_link_2_coco.STL" />
            </geometry>
            <material name="">
                <color rgba="0.792156862745098 0.819607843137255 0.933333333333333 1" />
            </material>
        </visual>
        <collision>
            <origin rpy="0 0 0" xyz="0 0 0" />
            <geometry>
                <mesh filename="package://my_robot_urdf/meshes/eef_link_2_coco.STL" />
            </geometry>
        </collision>
    </link>
    <joint name="coco_eef_joint_2_fixed_coco" type="fixed">
        <origin rpy="-1.5708 0 1.5708" xyz="-0.13985 0.00067738 0.085" />
        <parent link="coco_arm_link_6_coco" />
        <child link="coco_eef_link_2_coco" />
        <axis xyz="0 0 0" />
    </joint>
    <link name="yuzi_base_link_yuzi">
        <inertial>
            <origin rpy="0 0 0" xyz="-5.25107086452931E-18 -9.69114882893545E-18 0.131559716820544" />
            <mass value="13.926198063469" />
            <inertia ixx="0.150359375184122" ixy="6.0351097491869E-18" ixz="-1.94834723594448E-17" iyy="0.150359375184122" iyz="-1.44976161137733E-17" izz="0.11575755967506" />
        </inertial>
        <visual>
            <origin rpy="0 0 0" xyz="0 0 0" />
            <geometry>
                <mesh filename="package://my_robot_urdf/meshes/base_link_yuzi.STL" />
            </geometry>
            <material name="">
                <color rgba="0.792156862745098 0.819607843137255 0.933333333333333 1" />
            </material>
        </visual>
        <collision>
            <origin rpy="0 0 0" xyz="0 0 0" />
            <geometry>
                <mesh filename="package://my_robot_urdf/meshes/base_link_yuzi.STL" />
            </geometry>
        </collision>
    </link>
    <!-- Define the joint connecting this arm to the parent link -->
    <joint name="yuzi_base_joint_yuzi" type="fixed">
        <origin rpy="0 0 0" xyz="1 0 0.1" />
        <parent link="central_base_link" />
        <child link="yuzi_base_link_yuzi" />
    </joint>
    <link name="yuzi_arm_link_1_yuzi">
        <inertial>
            <origin rpy="0 0 0" xyz="0.0393277653963038 1.00151935086465E-07 0.150866622191122" />
            <mass value="17.6840361237851" />
            <inertia ixx="0.387077403080444" ixy="3.67268000731293E-07" ixz="-0.0824473388415476" iyy="0.281535059283111" iyz="6.77341185639246E-08" izz="0.349932526197817" />
        </inertial>
        <visual>
            <origin rpy="0 0 0" xyz="0 0 0" />
            <geometry>
                <mesh filename="package://my_robot_urdf/meshes/arm_link_1_yuzi.STL" />
            </geometry>
            <material name="">
                <color rgba="0.780392156862745 0.8 0.788235294117647 1" />
            </material>
        </visual>
        <collision>
            <origin rpy="0 0 0" xyz="0 0 0" />
            <geometry>
                <mesh filename="package://my_robot_urdf/meshes/arm_link_1_yuzi.STL" />
            </geometry>
        </collision>
    </link>
    <joint name="yuzi_arm_joint_1_yuzi" type="revolute">
        <origin rpy="0 0 0" xyz="0 0 0.274" />
        <parent link="yuzi_base_link_yuzi" />
        <child link="yuzi_arm_link_1_yuzi" />
        <axis xyz="0 0 1" />
        <limit effort="0" lower="-3.1416" upper="3.1416" velocity="0" />
    </joint>
    <link name="yuzi_arm_link_2_yuzi">
        <inertial>
            <origin rpy="0 0 0" xyz="5.931859369257E-07 -0.202994951659398 -0.00270543986390563" />
            <mass value="21.695061095067" />
            <inertia ixx="0.29491156513822" ixy="2.31415083687633E-06" ixz="1.23997830829163E-09" iyy="0.0783160010403902" iyz="0.000394743850237622" izz="0.301877815458434" />
        </inertial>
        <visual>
            <origin rpy="0 0 0" xyz="0 0 0" />
            <geometry>
                <mesh filename="package://my_robot_urdf/meshes/arm_link_2_yuzi.STL" />
            </geometry>
            <material name="">
                <color rgba="0.780392156862745 0.8 0.788235294117647 1" />
            </material>
        </visual>
        <collision>
            <origin rpy="0 0 0" xyz="0 0 0" />
            <geometry>
                <mesh filename="package://my_robot_urdf/meshes/arm_link_2_yuzi.STL" />
            </geometry>
        </collision>
    </link>
    <joint name="yuzi_arm_joint_2_yuzi" type="revolute">
        <origin rpy="-1.5708 0 3.1416" xyz="0.15 0 0.29" />
        <parent link="yuzi_arm_link_1_yuzi" />
        <child link="yuzi_arm_link_2_yuzi" />
        <axis xyz="0 0 -1" />
        <limit effort="0" lower="-1.5708" upper="1.5708" velocity="0" />
    </joint>
    <link name="yuzi_arm_link_3_yuzi">
        <inertial>
            <origin rpy="0 0 0" xyz="0.000448863422053053 -0.0261515151771508 -0.00178825757800023" />
            <mass value="4.48725682214162" />
            <inertia ixx="0.00921991972060868" ixy="4.02687063686657E-19" ixz="-7.15729755686699E-35" iyy="0.0233991913614871" iyz="1.50053365905829E-35" izz="0.0219081787552183" />
        </inertial>
        <visual>
            <origin rpy="0 0 0" xyz="0 0 0" />
            <geometry>
                <mesh filename="package://my_robot_urdf/meshes/arm_link_3_yuzi.STL" />
            </geometry>
            <material name="">
                <color rgba="0.792156862745098 0.819607843137255 0.933333333333333 1" />
            </material>
        </visual>
        <collision>
            <origin rpy="0 0 0" xyz="0 0 0" />
            <geometry>
                <mesh filename="package://my_robot_urdf/meshes/arm_link_3_yuzi.STL" />
            </geometry>
        </collision>
    </link>
    <joint name="yuzi_arm_joint_3_yuzi" type="revolute">
        <origin rpy="0 0 0" xyz="0 -0.575 0" />
        <parent link="yuzi_arm_link_2_yuzi" />
        <child link="yuzi_arm_link_3_yuzi" />
        <axis xyz="0 0 -1" />
        <limit effort="0" lower="-1.5708" upper="1.5708" velocity="0" />
    </joint>
    <link name="yuzi_arm_link_4_yuzi">
        <inertial>
            <origin rpy="0 0 0" xyz="6.66133814775094E-16 0.000932919736385606 0.288902507196118" />
            <mass value="7.8906783291211" />
            <inertia ixx="0.0897241931118627" ixy="-2.23893475246992E-19" ixz="-9.51519221962284E-19" iyy="0.0881400417573612" iyz="-0.000989909842324874" izz="0.0169814358788831" />
        </inertial>
        <visual>
            <origin rpy="0 0 0" xyz="0 0 0" />
            <geometry>
                <mesh filename="package://my_robot_urdf/meshes/arm_link_4_yuzi.STL" />
            </geometry>
            <material name="">
                <color rgba="0.792156862745098 0.819607843137255 0.933333333333333 1" />
            </material>
        </visual>
        <collision>
            <origin rpy="0 0 0" xyz="0 0 0" />
            <geometry>
                <mesh filename="package://my_robot_urdf/meshes/arm_link_4_yuzi.STL" />
            </geometry>
        </collision>
    </link>
    <joint name="yuzi_arm_joint_4_yuzi" type="revolute">
        <origin rpy="1.5708 0 -1.5708" xyz="-0.1295 -0.04 -0.003" />
        <parent link="yuzi_arm_link_3_yuzi" />
        <child link="yuzi_arm_link_4_yuzi" />
        <axis xyz="0 0 1" />
        <limit effort="0" lower="-3.1416" upper="3.1416" velocity="0" />
    </joint>
    <link name="yuzi_arm_link_5_yuzi">
        <inertial>
            <origin rpy="0 0 0" xyz="-0.0209881134676554 -1.11622497689368E-07 -0.00829305633881015" />
            <mass value="0.684392926448249" />
            <inertia ixx="0.000641087602858553" ixy="-1.13848125275888E-09" ixz="0.000110196226559993" iyy="0.00118845959430424" iyz="8.1268868198354E-12" izz="0.0013177404399051" />
        </inertial>
        <visual>
            <origin rpy="0 0 0" xyz="0 0 0" />
            <geometry>
                <mesh filename="package://my_robot_urdf/meshes/arm_link_5_yuzi.STL" />
            </geometry>
            <material name="">
                <color rgba="0.792156862745098 0.819607843137255 0.933333333333333 1" />
            </material>
        </visual>
        <collision>
            <origin rpy="0 0 0" xyz="0 0 0" />
            <geometry>
                <mesh filename="package://my_robot_urdf/meshes/arm_link_5_yuzi.STL" />
            </geometry>
        </collision>
    </link>
    <joint name="yuzi_arm_joint_5_yuzi" type="revolute">
        <origin rpy="-1.5708 1.5708 0" xyz="0 0 0.5455" />
        <parent link="yuzi_arm_link_4_yuzi" />
        <child link="yuzi_arm_link_5_yuzi" />
        <axis xyz="0 0 1" />
        <limit effort="0" lower="-1.5708" upper="1.5708" velocity="0" />
    </joint>
    <link name="yuzi_arm_link_6_yuzi">
        <inertial>
            <origin rpy="0 0 0" xyz="-1.11022302462516E-15 1.66967134562768E-15 0.0364608960848188" />
            <mass value="0.190738563830904" />
            <inertia ixx="0.000165744627457126" ixy="2.87815384189059E-22" ixz="-1.96348501644814E-20" iyy="0.000161337003377479" iyz="8.04929607286269E-21" izz="8.21544962643498E-05" />
        </inertial>
        <visual>
            <origin rpy="0 0 0" xyz="0 0 0" />
            <geometry>
                <mesh filename="package://my_robot_urdf/meshes/arm_link_6_yuzi.STL" />
            </geometry>
            <material name="">
                <color rgba="0.792156862745098 0.819607843137255 0.933333333333333 1" />
            </material>
        </visual>
        <collision>
            <origin rpy="0 0 0" xyz="0 0 0" />
            <geometry>
                <mesh filename="package://my_robot_urdf/meshes/arm_link_6_yuzi.STL" />
            </geometry>
        </collision>
    </link>
    <joint name="yuzi_arm_joint_6_yuzi" type="revolute">
        <origin rpy="-1.5708 0 1.5708" xyz="-0.085 0 0" />
        <parent link="yuzi_arm_link_5_yuzi" />
        <child link="yuzi_arm_link_6_yuzi" />
        <axis xyz="0 0 1" />
        <limit effort="0" lower="-3.1416" upper="3.1416" velocity="0" />
    </joint>
    <link name="yuzi_eef_link_yuzi">
        <inertial>
            <origin rpy="0 0 0" xyz="-0.00215923528943862 -1.34441069388203E-17 -0.0685050835227634" />
            <mass value="0.190738563830904" />
            <inertia ixx="0.000165661665669484" ixy="6.02940705304147E-22" ixz="-2.63209119423623E-06" iyy="0.000161337003377479" iyz="1.01035149151913E-20" izz="8.22374580519918E-05" />
        </inertial>
        <visual>
            <origin rpy="0 0 0" xyz="0 0 0" />
            <geometry>
                <mesh filename="package://my_robot_urdf/meshes/eef_link_yuzi.STL" />
            </geometry>
            <material name="">
                <color rgba="0.792156862745098 0.819607843137255 0.933333333333333 1" />
            </material>
        </visual>
        <collision>
            <origin rpy="0 0 0" xyz="0 0 0" />
            <geometry>
                <mesh filename="package://my_robot_urdf/meshes/eef_link_yuzi.STL" />
            </geometry>
        </collision>
    </link>
    <joint name="yuzi_eef_joint_fixed_yuzi" type="fixed">
        <origin rpy="0 -0.031509 0" xyz="0 0 0.105" />
        <parent link="yuzi_arm_link_6_yuzi" />
        <child link="yuzi_eef_link_yuzi" />
        <axis xyz="0 0 0" />
    </joint>
    <transmission name="trans_alex_arm_joint_1_alex">
        <type>transmission_interface/SimpleTransmission</type>
        <joint name="alex_arm_joint_1_alex">
            <hardwareInterface>hardware_interface/EffortJointInterface</hardwareInterface>
        </joint>
        <actuator name="alex_arm_joint_1_alex_motor">
            <hardwareInterface>hardware_interface/EffortJointInterface</hardwareInterface>
            <mechanicalReduction>1</mechanicalReduction>
        </actuator>
    </transmission>
    <transmission name="trans_alex_arm_joint_2_alex">
        <type>transmission_interface/SimpleTransmission</type>
        <joint name="alex_arm_joint_2_alex">
            <hardwareInterface>hardware_interface/EffortJointInterface</hardwareInterface>
        </joint>
        <actuator name="alex_arm_joint_2_alex_motor">
            <hardwareInterface>hardware_interface/EffortJointInterface</hardwareInterface>
            <mechanicalReduction>1</mechanicalReduction>
        </actuator>
    </transmission>
    <transmission name="trans_alex_arm_joint_3_alex">
        <type>transmission_interface/SimpleTransmission</type>
        <joint name="alex_arm_joint_3_alex">
            <hardwareInterface>hardware_interface/EffortJointInterface</hardwareInterface>
        </joint>
        <actuator name="alex_arm_joint_3_alex_motor">
            <hardwareInterface>hardware_interface/EffortJointInterface</hardwareInterface>
            <mechanicalReduction>1</mechanicalReduction>
        </actuator>
    </transmission>
    <transmission name="trans_alex_arm_joint_4_alex">
        <type>transmission_interface/SimpleTransmission</type>
        <joint name="alex_arm_joint_4_alex">
            <hardwareInterface>hardware_interface/EffortJointInterface</hardwareInterface>
        </joint>
        <actuator name="alex_arm_joint_4_alex_motor">
            <hardwareInterface>hardware_interface/EffortJointInterface</hardwareInterface>
            <mechanicalReduction>1</mechanicalReduction>
        </actuator>
    </transmission>
    <transmission name="trans_alex_arm_joint_5_alex">
        <type>transmission_interface/SimpleTransmission</type>
        <joint name="alex_arm_joint_5_alex">
            <hardwareInterface>hardware_interface/EffortJointInterface</hardwareInterface>
        </joint>
        <actuator name="alex_arm_joint_5_alex_motor">
            <hardwareInterface>hardware_interface/EffortJointInterface</hardwareInterface>
            <mechanicalReduction>1</mechanicalReduction>
        </actuator>
    </transmission>
    <transmission name="trans_alex_arm_joint_6_alex">
        <type>transmission_interface/SimpleTransmission</type>
        <joint name="alex_arm_joint_6_alex">
            <hardwareInterface>hardware_interface/EffortJointInterface</hardwareInterface>
        </joint>
        <actuator name="alex_arm_joint_6_alex_motor">
            <hardwareInterface>hardware_interface/EffortJointInterface</hardwareInterface>
            <mechanicalReduction>1</mechanicalReduction>
        </actuator>
    </transmission>
    <transmission name="trans_coco_joint_link_1_coco">
        <type>transmission_interface/SimpleTransmission</type>
        <joint name="coco_joint_link_1_coco">
            <hardwareInterface>hardware_interface/EffortJointInterface</hardwareInterface>
        </joint>
        <actuator name="coco_joint_link_1_coco_motor">
            <hardwareInterface>hardware_interface/EffortJointInterface</hardwareInterface>
            <mechanicalReduction>1</mechanicalReduction>
        </actuator>
    </transmission>
    <transmission name="trans_coco_joint_link_2_coco">
        <type>transmission_interface/SimpleTransmission</type>
        <joint name="coco_joint_link_2_coco">
            <hardwareInterface>hardware_interface/EffortJointInterface</hardwareInterface>
        </joint>
        <actuator name="coco_joint_link_2_coco_motor">
            <hardwareInterface>hardware_interface/EffortJointInterface</hardwareInterface>
            <mechanicalReduction>1</mechanicalReduction>
        </actuator>
    </transmission>
    <transmission name="trans_coco_joint_link_3_coco">
        <type>transmission_interface/SimpleTransmission</type>
        <joint name="coco_joint_link_3_coco">
            <hardwareInterface>hardware_interface/EffortJointInterface</hardwareInterface>
        </joint>
        <actuator name="coco_joint_link_3_coco_motor">
            <hardwareInterface>hardware_interface/EffortJointInterface</hardwareInterface>
            <mechanicalReduction>1</mechanicalReduction>
        </actuator>
    </transmission>
    <transmission name="trans_coco_joint_link_4_coco">
        <type>transmission_interface/SimpleTransmission</type>
        <joint name="coco_joint_link_4_coco">
            <hardwareInterface>hardware_interface/EffortJointInterface</hardwareInterface>
        </joint>
        <actuator name="coco_joint_link_4_coco_motor">
            <hardwareInterface>hardware_interface/EffortJointInterface</hardwareInterface>
            <mechanicalReduction>1</mechanicalReduction>
        </actuator>
    </transmission>
    <transmission name="trans_coco_joint_link_5_coco">
        <type>transmission_interface/SimpleTransmission</type>
        <joint name="coco_joint_link_5_coco">
            <hardwareInterface>hardware_interface/EffortJointInterface</hardwareInterface>
        </joint>
        <actuator name="coco_joint_link_5_coco_motor">
            <hardwareInterface>hardware_interface/EffortJointInterface</hardwareInterface>
            <mechanicalReduction>1</mechanicalReduction>
        </actuator>
    </transmission>
    <transmission name="trans_coco_arm_joint_6_coco">
        <type>transmission_interface/SimpleTransmission</type>
        <joint name="coco_arm_joint_6_coco">
            <hardwareInterface>hardware_interface/EffortJointInterface</hardwareInterface>
        </joint>
        <actuator name="coco_arm_joint_6_coco_motor">
            <hardwareInterface>hardware_interface/EffortJointInterface</hardwareInterface>
            <mechanicalReduction>1</mechanicalReduction>
        </actuator>
    </transmission>
    <transmission name="trans_yuzi_arm_joint_1_yuzi">
        <type>transmission_interface/SimpleTransmission</type>
        <joint name="yuzi_arm_joint_1_yuzi">
            <hardwareInterface>hardware_interface/EffortJointInterface</hardwareInterface>
        </joint>
        <actuator name="yuzi_arm_joint_1_yuzi_motor">
            <hardwareInterface>hardware_interface/EffortJointInterface</hardwareInterface>
            <mechanicalReduction>1</mechanicalReduction>
        </actuator>
    </transmission>
    <transmission name="trans_yuzi_arm_joint_2_yuzi">
        <type>transmission_interface/SimpleTransmission</type>
        <joint name="yuzi_arm_joint_2_yuzi">
            <hardwareInterface>hardware_interface/EffortJointInterface</hardwareInterface>
        </joint>
        <actuator name="yuzi_arm_joint_2_yuzi_motor">
            <hardwareInterface>hardware_interface/EffortJointInterface</hardwareInterface>
            <mechanicalReduction>1</mechanicalReduction>
        </actuator>
    </transmission>
    <transmission name="trans_yuzi_arm_joint_3_yuzi">
        <type>transmission_interface/SimpleTransmission</type>
        <joint name="yuzi_arm_joint_3_yuzi">
            <hardwareInterface>hardware_interface/EffortJointInterface</hardwareInterface>
        </joint>
        <actuator name="yuzi_arm_joint_3_yuzi_motor">
            <hardwareInterface>hardware_interface/EffortJointInterface</hardwareInterface>
            <mechanicalReduction>1</mechanicalReduction>
        </actuator>
    </transmission>
    <transmission name="trans_yuzi_arm_joint_4_yuzi">
        <type>transmission_interface/SimpleTransmission</type>
        <joint name="yuzi_arm_joint_4_yuzi">
            <hardwareInterface>hardware_interface/EffortJointInterface</hardwareInterface>
        </joint>
        <actuator name="yuzi_arm_joint_4_yuzi_motor">
            <hardwareInterface>hardware_interface/EffortJointInterface</hardwareInterface>
            <mechanicalReduction>1</mechanicalReduction>
        </actuator>
    </transmission>
    <transmission name="trans_yuzi_arm_joint_5_yuzi">
        <type>transmission_interface/SimpleTransmission</type>
        <joint name="yuzi_arm_joint_5_yuzi">
            <hardwareInterface>hardware_interface/EffortJointInterface</hardwareInterface>
        </joint>
        <actuator name="yuzi_arm_joint_5_yuzi_motor">
            <hardwareInterface>hardware_interface/EffortJointInterface</hardwareInterface>
            <mechanicalReduction>1</mechanicalReduction>
        </actuator>
    </transmission>
    <transmission name="trans_yuzi_arm_joint_6_yuzi">
        <type>transmission_interface/SimpleTransmission</type>
        <joint name="yuzi_arm_joint_6_yuzi">
            <hardwareInterface>hardware_interface/EffortJointInterface</hardwareInterface>
        </joint>
        <actuator name="yuzi_arm_joint_6_yuzi_motor">
            <hardwareInterface>hardware_interface/EffortJointInterface</hardwareInterface>
            <mechanicalReduction>1</mechanicalReduction>
        </actuator>
    </transmission>
    <gazebo>
        <plugin name="gazebo_ros_control" filename="libgazebo_ros_control.so">
            <robotNamespace>/</robotNamespace>
        </plugin>
    </gazebo>
</robot>

